Workbook

Sheet Summary
B2: AFCONS INFRASTRUCTURE LIMITED
B3: Equity Research — Investment Summary
B5: INVESTMENT RECOMMENDATION
B7: Recommendation: | C7: =Valuation!E83 -> HOLD
B8: Target Price (Blended): | C8: =Valuation!E79 -> 349.56217
B9: Current Market Price: | C9: =Valuation!C40 -> 305.45
B10: Upside / (Downside): | C10: =Valuation!E82 -> 0.14441698
B13: MARKET DATA
B14: Shares Outstanding (Cr): | C14: =Valuation!C38 -> 36.798
B15: Market Cap (₹ Cr): | C15: =Valuation!C40*Valuation!C38 -> 11239.949
B16: Net Debt FY26 (₹ Cr): | C16: =Historicals!G216-Historicals!G225 -> 2652.38
B17: Enterprise Value (₹ Cr): | C17: =C15+C16 -> 13892.329
B20: FINANCIAL SUMMARY (₹ Cr)
C21: FY23A | D21: FY24A | E21: FY25A | F21: FY26A | G21: FY27E | H21: FY28E | I21: FY29E
B22: Revenue from Operations | C22: =Historicals!D8 -> 12637.38 | D22: =Historicals!E8 -> 13267.5 | E22: =Historicals!F8 -> 12548.42 | F22: =Historicals!G8 -> 11948.38 | G22: =Projections!E40 -> 10011.261 | H22: =Projections!F40 -> 12118.851 | I22: =Projections!G40 -> 14725.412
B23: YoY Growth % | D23: =D22/C22-1 -> 0.049861601 | E23: =E22/D22-1 -> -0.054198606 | F23: =F22/E22-1 -> -0.047817972 | G23: =G22/F22-1 -> -0.16212402 | H23: =H22/G22-1 -> 0.21052194 | I23: =I22/H22-1 -> 0.21508319
B24: EBITDA (excl Other Income) | C24: =Historicals!D210 -> 1310.61 | D24: =Historicals!E210 -> 1365.03 | E24: =Historicals!F210 -> 1355.96 | F24: =Historicals!G210 -> 1217.11 | G24: =Projections!E58 -> 1051.1824 | H24: =Projections!F58 -> 1393.6678 | I24: =Projections!G58 -> 1722.8732
B25: EBITDA Margin % | C25: =C24/C22 -> 0.103709 | D25: =D24/D22 -> 0.10288525 | E25: =E24/E22 -> 0.10805823 | F25: =F24/F22 -> 0.10186402 | G25: =G24/G22 -> 0.105 | H25: =H24/H22 -> 0.115 | I25: =I24/I22 -> 0.117
B26: PAT | C26: =Historicals!D31 -> 410.86 | D26: =Historicals!E31 -> 449.76 | E26: =Historicals!F31 -> 486.79 | F26: =Historicals!G31 -> 250.74 | G26: =Projections!E70 -> 431.7658 | H26: =Projections!F70 -> 697.0955 | I26: =Projections!G70 -> 968.31549
B27: EPS (₹) | C27: =Historicals!D51 -> 12.06 | D27: =Historicals!E51 -> 13.2 | E27: =Historicals!F51 -> 13.24 | F27: =Historicals!G51 -> 6.82 | G27: =Projections!E72 -> 11.733404 | H27: =Projections!F72 -> 18.943842 | I27: =Projections!G72 -> 26.314351
B28: Closing Order Book | C28: =Historicals!D243 -> 30406 | D28: =Historicals!E243 -> 30961 | E28: =Historicals!F243 -> 36868.61 | F28: =Historicals!G243 -> 32495.65 | G28: =Projections!E9 -> 36395.128 | H28: =Projections!F9 -> 42946.251 | I28: =Projections!G9 -> 49388.189
B29: Book-to-Bill (x) | C29: =C28/C22 -> 2.4060367 | D29: =D28/D22 -> 2.3335971 | E29: =E28/E22 -> 2.9381077 | F29: =F28/F22 -> 2.7196699 | G29: =G28/G22 -> 3.6354191 | H29: =H28/H22 -> 3.5437561 | I29: =I28/I22 -> 3.3539428
B32: VALUATION SNAPSHOT
B33: Method | C33: Implied Price (₹) | D33: Weight | E33: Contribution (₹)
B34: DCF | C34: =Valuation!C39 -> 359.41576 | D34: =Valuation!D75 -> 0.4 | E34: =C34*D34 -> 143.7663
B35: EV/EBITDA (FY28E) | C35: =Valuation!E68 -> 344.52867 | D35: =Valuation!D76 -> 0.3 | E35: =C35*D35 -> 103.3586
B36: P/E (FY28E) | C36: =Valuation!E69 -> 378.87684 | D36: =Valuation!D77 -> 0.2 | E36: =C36*D36 -> 75.775369
B37: P/B (FY26) | C37: =Valuation!E70 -> 266.61895 | D37: =Valuation!D78 -> 0.1 | E37: =C37*D37 -> 26.661895
B38: BLENDED TARGET | C38: =Valuation!E79 -> 349.56217 | D38: =SUM(D34:D37) -> 1 | E38: =SUM(E34:E37) -> 349.56217
B41: INVESTMENT THESIS
B42: Positives
B43: • Mgmt guidance ₹30,000 Cr inflow FY27 (vs FY26 ₹4,125 Cr) — recovery trajectory
B44: • Specialty EPC moat: Marine, Underground Metro, Hydro (peer-leading margins ~12% vs sector 8.5%)
B45: • Diversified OB ₹32,500 Cr — 2.7x book-to-bill provides multi-year visibility
B46: • Post-IPO balance sheet flexibility — improving credit profile, supplier negotiation leverage
B47: • Underpenetrated overseas opportunity (Africa, Middle East marine pipeline in L1)
B49: Risks
B50: • Geopolitical risk on overseas execution (FY26 Africa disruptions affected calibration)
B51: • Working capital intensive: ~118 days NWC FY26, contract assets ₹7,731 Cr (largest item)
B52: • Government client payment cycles — receivables stretched to 123 days FY26
...

Sheet Historicals
B2: AFCONS INFRASTRUCTURE — CONSOLIDATED HISTORICALS
B3: Every line item as reported. FY23 from AR 2022-23. FY24-26 from quarterly outcomes/Q4 IPs. ₹ Cr.
D5: FY23A | E5: FY24A | F5: FY25A | G5: FY26A | H5: Source
B6: CONSOLIDATED STATEMENT OF PROFIT AND LOSS (₹ Cr)
B7: Income
B8: Revenue from Operations | D8: 12637.38 | E8: 13267.5 | F8: 12548.42 | G8: 11948.38 | H8: FY23 AR; FY24-26 outcomes
B9: Other income (net) | D9: 206.71 | E9: 379.38 | F9: 474.35 | G9: 373.72 | H9: As reported
B10: Total Income | D10: =SUM(D8:D9) -> 12844.09 | E10: =SUM(E8:E9) -> 13646.88 | F10: =SUM(F8:F9) -> 13022.77 | G10: =SUM(G8:G9) -> 12322.1 | H10: Sum
B12: Expenses
B13: Cost of material consumed | D13: 3851.71 | E13: 4012.48 | F13: 3290.14 | G13: 2845.17 | H13: As reported
B14: Cost of Construction | D14: 5200.65 | E14: 5293.97 | F14: 5246.06 | G14: 5046.17 | H14: As reported
B15: Employee benefit expenses | D15: 1298.23 | E15: 1383.42 | F15: 1435.11 | G15: 1451.72 | H15: As reported
B16: Finance costs | D16: 446.66 | E16: 577.26 | F16: 629.2 | G16: 673.61 | H16: As reported
B17: Depreciation and amortisation expense | D17: 471.58 | E17: 494.53 | F17: 491.1 | G17: 453.92 | H17: As reported
B18: Other expenses | D18: 976.18 | E18: 1212.6 | F18: 1221.15 | G18: 1388.21 | H18: As reported
B19: Total Expenses | D19: =SUM(D13:D18) -> 12245.01 | E19: =SUM(E13:E18) -> 12974.26 | F19: =SUM(F13:F18) -> 12312.76 | G19: =SUM(G13:G18) -> 11858.8 | H19: Sum
B21: Profit before exceptional items & tax | D21: =D10-D19 -> 599.08 | E21: =E10-E19 -> 672.62 | F21: =F10-F19 -> 710.01 | G21: =G10-G19 -> 463.3 | H21: Total Income − Total Expenses
B22: Exceptional Items | D22: 0 | E22: 0 | F22: 0 | G22: 76.51 | H22: FY26: ₹76.51 Cr Labour Code
B23: Profit before tax | D23: =D21-D22 -> 599.08 | E23: =E21-E22 -> 672.62 | F23: =F21-F22 -> 710.01 | G23: =G21-G22 -> 386.79 | H23: PBEI − Exceptional
B25: Tax expense:
B26: (i) Current tax | D26: 189.43 | E26: 200.24 | F26: 275.93 | G26: 198.71 | H26: As reported
B27: (ii) Deferred tax − (credit) / charge | D27: -29.79 | E27: 7.24 | F27: -36.78 | G27: -64.86 | H27: As reported (negative = credit)
B28: (iii) Tax expense relating to earlier years (net) | D28: 28.58 | E28: 15.38 | F28: -15.93 | G28: 2.2 | H28: As reported
B29: Total tax expense | D29: =SUM(D26:D28) -> 188.22 | E29: =SUM(E26:E28) -> 222.86 | F29: =SUM(F26:F28) -> 223.22 | G29: =SUM(G26:G28) -> 136.05 | H29: Sum of (i)+(ii)+(iii)
B31: Profit after tax and exceptional items | D31: =D23-D29 -> 410.86 | E31: =E23-E29 -> 449.76 | F31: =F23-F29 -> 486.79 | G31: =G23-G29 -> 250.74 | H31: PBT − Tax
B33: Other Comprehensive Income (OCI)
B34: A) Items that will not be reclassified to P&L
B35: (a) Changes in fair value of equity investments (FVOCI), net of tax | D35: -0.4 | E35: 0.26 | F35: 0.01 | G35: -0.23 | H35: As reported
B36: (b) Remeasurements of defined benefit plans, net of tax | D36: -2.1 | E36: -8.51 | F36: -5.74 | G36: 15.94 | H36: As reported
B37: B) Items that will be reclassified to P&L
B38: (a) Exchange differences on translation of foreign operations | D38: 66.16 | E38: 7.59 | F38: -4.02 | G38: -7.38 | H38: As reported
B39: Other Comprehensive Income / (Loss) | D39: =SUM(D35:D38) -> 63.66 | E39: =SUM(E35:E38) -> -0.66 | F39: =SUM(F35:F38) -> -9.75 | G39: =SUM(G35:G38) -> 8.33 | H39: Sum
B41: Total Comprehensive Income for the year | D41: =D31+D39 -> 474.52 | E41: =E31+E39 -> 449.1 | F41: =F31+F39 -> 477.04 | G41: =G31+G39 -> 259.07 | H41: PAT + OCI
B43: Profit attributable to:
B44: − Owners of the Company | D44: 410.87 | E44: 449.76 | F44: 486.81 | G44: 251.5 | H44: As reported
B45: − Non-controlling interest | D45: -0.01 | E45: 0 | F45: -0.02 | G45: -0.76 | H45: As reported
B47: Paid-up equity share capital | D47: 71.97 | E47: 340.74 | F47: 367.78 | G47: 367.78 | H47: As reported (FV ₹10 each)
B48: Other equity (reserves) | D48: 2653.72 | E48: 3255.21 | F48: 4892.74 | G48: 5082.02 | H48: As reported
B50: Earnings per share (₹):
B51: Basic EPS | D51: 12.06 | E51: 13.2 | F51: 13.24 | G51: 6.82 | H51: As reported
...

Sheet Projections
B2: AFCONS INFRASTRUCTURE — PROJECTIONS
B3: FY27E-FY29E. ₹ Crore. Blue = inputs (flex these). Black = formulas. Green = links from Historicals.
D5: FY26A | E5: FY27E | F5: FY28E | G5: FY29E | H5: Driver / Reasoning
B6: ORDER BOOK FORECAST (₹ Cr)
B8: Total OB Growth % YoY | E8: 0.12 | F8: 0.18 | G8: 0.15 | H8: FY27: mgmt guided ₹30k Cr inflow → ~12% OB growth. FY28-29: ramp on bigger order book.
B9: Closing Total Order Book | D9: =Historicals!G243 -> 32495.65 | E9: =D9*(1+E8) -> 36395.128 | F9: =E9*(1+F8) -> 42946.251 | G9: =F9*(1+G8) -> 49388.189
B11: Segment OB Composition % (Forecast — flex these)
B12: Marine & Industrial | D12: =Historicals!G253 -> 0.15 | E12: 0.15 | F12: 0.14 | G12: 0.13 | H12: Marine: Overseas-heavy (Africa, Middle East). FY27 normalise from FY26 spike, slight moderation
B13: Surface Transport | D13: =Historicals!G254 -> 0.09 | E13: 0.09 | F13: 0.1 | G13: 0.1 | H13: Surface: Mgmt 'selective bidding' — share stays low. Slight uptick FY28+
B14: Urban Infra (Metro) | D14: =Historicals!G255 -> 0.28 | E14: 0.28 | F14: 0.29 | G14: 0.3 | H14: Metro: Mgmt highlighted Delhi MRTS Phase IV, Bangalore Metro pipeline → grows
B15: Urban Infra (Bridges) | D15: =Historicals!G256 -> 0.23 | E15: 0.23 | F15: 0.23 | G15: 0.23 | H15: Bridges: RRTS, elevated corridors. Stable share
B16: Hydro & Underground | D16: =Historicals!G257 -> 0.23 | E16: 0.23 | F16: 0.22 | G16: 0.22 | H16: Hydro: Mgmt cited Jamrani Dam, Basania Dam wins → roughly stable
B17: Oil & Gas | D17: =Historicals!G258 -> 0.02 | E17: 0.02 | F17: 0.02 | G17: 0.02 | H17: O&G: Mgmt 'small but selective'. Stays at 2%
B18: Sum (=100%) | D18: =SUM(D12:D17) -> 1 | E18: =SUM(E12:E17) -> 1 | F18: =SUM(F12:F17) -> 1 | G18: =SUM(G12:G17) -> 1
B20: EXECUTION RATE BUILD
B22: FY26 Baseline Execution Rate (Rev / Opening OB) | D22: =Historicals!G8/Historicals!F243 -> 0.32408002 | H22: Baseline = FY26 Revenue ÷ FY25 closing OB
B24: Segment Execution Adjustment (pp vs baseline) — flex these
B25: Marine & Industrial | E25: -0.03 | F25: 0.01 | G25: 0.02 | H25: FY27 -3pp: heavy overseas exposure (Africa) — geopolitical drag persists. FY28-29: recovery.
B26: Surface Transport | E26: -0.02 | F26: 0 | G26: 0.01 | H26: FY27 -2pp: mgmt cited 'selective bidding'; new contracts ramp slower. FY28-29: modest improvement.
B27: Urban Infra (Metro) | E27: -0.01 | F27: 0.01 | G27: 0.02 | H27: FY27 -1pp: HSR & metro execution continues but slower start on FY27 new wins. Recovery FY28-29.
B28: Urban Infra (Bridges) | E28: -0.01 | F28: 0.01 | G28: 0.02 | H28: FY27 -1pp: similar to Metro — ramp lag. Recovery FY28-29.
B29: Hydro & Underground | E29: -0.02 | F29: 0.01 | G29: 0.02 | H29: FY27 -2pp: Hydro/tunnels are long-cycle; new wins (Jamrani, Basania) take time to ramp.
B30: Oil & Gas | E30: 0 | F30: 0 | G30: 0.01 | H30: FY27 0pp: small base, mgmt 'selective' — stable execution rate.
B32: Weighted Avg Execution Adjustment
B33: Weighted Adjustment (weighted by opening OB share) | E33: =SUMPRODUCT(E25:E30,D12:D17) -> -0.016 | F33: =SUMPRODUCT(F25:F30,E12:E17) -> 0.0089 | G33: =SUMPRODUCT(G25:G30,F12:F17) -> 0.0188 | H33: Σ(segment adjustment × prior-year OB share)
B35: Final Execution Rate (Baseline + Weighted Adj) | D35: =D22 -> 0.32408002 | E35: =$D$22+E33 -> 0.30808002 | F35: =$D$22+F33 -> 0.33298002 | G35: =$D$22+G33 -> 0.34288002 | H35: FY26 Baseline + Weighted Adjustment
B38: PROJECTED P&L (₹ Cr)
B40: Revenue from Operations | D40: =Historicals!G8 -> 11948.38 | E40: =D9*E35 -> 10011.261 | F40: =E9*F35 -> 12118.851 | G40: =F9*G35 -> 14725.412 | H40: Opening OB times Execution Rate
B41: YoY Growth % | E41: =E40/D40-1 -> -0.16212402 | F41: =F40/E40-1 -> 0.21052194 | G41: =G40/F40-1 -> 0.21508319
B42: Other Income | D42: =Historicals!G9 -> 373.72 | E42: =E40*0.03 -> 300.33782 | F42: =F40*0.03 -> 363.56552 | G42: =G40*0.03 -> 441.76235 | H42: FY27-29: 3.0% of Revenue from Ops (steady-state treasury income)
B43: Total Income | D43: =D40+D42 -> 12322.1 | E43: =E40+E42 -> 10311.598 | F43: =F40+F42 -> 12482.416 | G43: =G40+G42 -> 15167.174
B45: Operating Expenses (forecasted as % of Revenue from Ops)
B46: Cost of Material Consumed (% Revenue) | D46: =Historicals!G11/Historicals!G8 -> 0 | E46: 0.245 | F46: 0.24 | G46: 0.24 | H46: FY26 base 23.8%. Mgmt: 'procurement scale + better commodity hedging' → modest improvement. Stable from FY28.
B47: Cost of Construction (Sub-contract) (% Revenue) | D47: =Historicals!G12/Historicals!G8 -> 0 | E47: 0.42 | F47: 0.42 | G47: 0.42 | H47: FY26 base 42.2%. Mgmt: 'sub-contract intensity stable'. Held flat — biggest cost line, low operating leverage.
B48: Employee Expenses (% Revenue) | D48: =Historicals!G13/Historicals!G8 -> 0.23812182 | E48: 0.115 | F48: 0.11 | G48: 0.108 | H48: FY26 base 12.2%. Mgmt: 'employee cost grows slower than revenue as we scale'. Operating leverage on fixed staff.
B49: Other Expenses (% Revenue) | D49: =Historicals!G14/Historicals!G8 -> 0.42233089 | E49: 0.115 | F49: 0.115 | G49: 0.115 | H49: FY26 base 12.9%. Labour code drag (~60bps) FY26. FY27-29: normalize as labour code base-effect washes out.
B51: Cost Lines (₹ Cr) = % × Revenue from Ops
B52: Cost of Material Consumed | D52: =Historicals!G11 -> 0 | E52: =E46*E40 -> 2452.7589 | F52: =F46*F40 -> 2908.5241 | G52: =G46*G40 -> 3534.0988
B53: Cost of Construction | D53: =Historicals!G12 -> 0 | E53: =E47*E40 -> 4204.7295 | F53: =F47*F40 -> 5089.9172 | G53: =G47*G40 -> 6184.6729
B54: Employee Expenses | D54: =Historicals!G13 -> 2845.17 | E54: =E48*E40 -> 1151.295 | F54: =F48*F40 -> 1333.0736 | G54: =G48*G40 -> 1590.3444
...

Sheet Valuation
B2: AFCONS INFRASTRUCTURE — VALUATION
B3: DCF (6-year explicit + Gordon TV) and Relative Valuation
B5: DISCOUNTED CASH FLOW (DCF)
B7: Cost of Capital Build
B8: Risk-Free Rate (10Y G-Sec) | C8: 0.068 | D8: RBI 10Y G-Sec yield as of May 2026
B9: Equity Risk Premium (India) | C9: 0.06 | D9: Damodaran 2026 India ERP
B10: Beta (Levered) | C10: 1.05 | D10: EPC peer regression
B11: Cost of Equity (Ke) [CAPM] | C11: =C8+C10*C9 -> 0.131 | D11: Rf + Beta × ERP
B12: Pre-tax Cost of Debt (Kd) | C12: 0.105 | D12: Same as model assumption (constant)
B13: Effective Tax Rate | C13: 0.255 | D13: Concessional regime
B14: After-tax Cost of Debt | C14: =C12*(1-C13) -> 0.078225 | D14: Kd × (1−T)
B15: Target D / (D+E) | C15: 0.15 | D15: Conservative target leverage post-IPO
B16: Target E / (D+E) | C16: =1-C15 -> 0.85 | D16: 1 − D/(D+E)
B17: WACC | C17: =C16*C11+C15*C14 -> 0.12308375 | D17: Weighted average
B18: Terminal Growth (g) | C18: 0.04 | D18: India LT nominal GDP × moderation factor
B21: FCFF Projection (₹ Cr)
C22: FY27E | D22: FY28E | E22: FY29E | F22: FY30E | G22: FY31E | H22: FY32E
B23: FCFF | C23: =Projections!E159 -> 1423.8165 | D23: =Projections!F159 -> 654.79604 | E23: =Projections!G159 -> 1273.7806 | F23: =E23*(1+F24) -> 1426.6343 | G23: =F23*(1+G24) -> 1569.2977 | H23: =G23*(1+H24) -> 1694.8415
B24: Growth rate (input for FY30-32) | F24: 0.12 | G24: 0.1 | H24: 0.08
B25: Terminal Value (at FY32) | H25: =H23*(1+C18)/(C17-C18) -> 21215.162
B26: Year (from valuation date) | C26: 1 | D26: 2 | E26: 3 | F26: 4 | G26: 5 | H26: 6
B27: Discount Factor | C27: =1/(1+$C$17)^C26 -> 0.89040555 | D27: =1/(1+$C$17)^D26 -> 0.79282204 | E27: =1/(1+$C$17)^E26 -> 0.70593314 | F27: =1/(1+$C$17)^F26 -> 0.62856678 | G27: =1/(1+$C$17)^G26 -> 0.55967935 | H27: =1/(1+$C$17)^H26 -> 0.4983416
B28: PV of FCFF | C28: =C23*C27 -> 1267.7741 | D28: =D23*D27 -> 519.13673 | E28: =E23*E27 -> 899.20396 | F28: =F23*F27 -> 896.73493 | G28: =G23*G27 -> 878.30353 | H28: =H23*H27 -> 844.61004
B29: PV of Terminal Value | H29: =H25*H27 -> 10572.398
B32: DCF Valuation Summary
B33: Sum of PV(FCFF) FY27-32 | C33: =SUM(C28:H28) -> 5305.7633
B34: PV of Terminal Value | C34: =H29 -> 10572.398
B35: Enterprise Value (EV) | C35: =C33+C34 -> 15878.161
B36: Less: Net Debt (FY26) | C36: =-(Historicals!G216-Historicals!G225) -> -2652.38
B37: Equity Value | C37: =C35+C36 -> 13225.781
B38: Shares Outstanding (Cr) | C38: 36.798
B39: DCF Implied Price (₹/share) | C39: =C37/C38 -> 359.41576
B40: Current Market Price (₹) | C40: 305.45
B41: Upside / (Downside) | C41: =C39/C40-1 -> 0.17667623
B43: DCF Sensitivity — Implied Price (₹) | WACC (cols) × Terminal Growth (rows)
B45: g \ WACC → | D45: =$C$17+-0.015 -> 0.10808375 | E45: =$C$17+-0.01 -> 0.11308375 | F45: =$C$17+-0.005 -> 0.11808375 | G45: =$C$17+0 -> 0.12308375 | H45: =$C$17+0.005 -> 0.12808375 | I45: =$C$17+0.01 -> 0.13308375 | J45: =$C$17+0.015 -> 0.13808375
B46: 0.03 | D46: =($C$23/(1+($C$17+-0.015))^1+$D$23/(1+($C$17+-0.015))^2+$E$23/(1+($C$17+-0.015))^3+$F$23/(1+($C$17+-0.015))^4+$G$23/(1+($C$17+-0.015))^5+$H$23/(1+($C$17+-0.015))^6+($H$23*(1+$B46)/(($C$17+-0.015)-$B46))/(1+($C$17+-0.015))^6-(Historicals!G216-Historicals!G225))/C38 -> 407.10395 | E46: =($C$23/(1+($C$17+-0.01))^1+$D$23/(1+($C$17+-0.01))^2+$E$23/(1+($C$17+-0.01))^3+$F$23/(1+($C$17+-0.01))^4+$G$23/(1+($C$17+-0.01))^5+$H$23/(1+($C$17+-0.01))^6+($H$23*(1+$B46)/(($C$17+-0.01)-$B46))/(1+($C$17+-0.01))^6-(Historicals!G216-Historicals!G225))/C38 -> 376.81337 | F46: =($C$23/(1+($C$17+-0.005))^1+$D$23/(1+($C$17+-0.005))^2+$E$23/(1+($C$17+-0.005))^3+$F$23/(1+($C$17+-0.005))^4+$G$23/(1+($C$17+-0.005))^5+$H$23/(1+($C$17+-0.005))^6+($H$23*(1+$B46)/(($C$17+-0.005)-$B46))/(1+($C$17+-0.005))^6-(Historicals!G216-Historicals!G225))/C38 -> 349.99351 | G46: =($C$23/(1+($C$17+0))^1+$D$23/(1+($C$17+0))^2+$E$23/(1+($C$17+0))^3+$F$23/(1+($C$17+0))^4+$G$23/(1+($C$17+0))^5+$H$23/(1+($C$17+0))^6+($H$23*(1+$B46)/(($C$17+0)-$B46))/(1+($C$17+0))^6-(Historicals!G216-Historicals!G225))/C38 -> 326.08431 | H46: =($C$23/(1+($C$17+0.005))^1+$D$23/(1+($C$17+0.005))^2+$E$23/(1+($C$17+0.005))^3+$F$23/(1+($C$17+0.005))^4+$G$23/(1+($C$17+0.005))^5+$H$23/(1+($C$17+0.005))^6+($H$23*(1+$B46)/(($C$17+0.005)-$B46))/(1+($C$17+0.005))^6-(Historicals!G216-Historicals!G225))/C38 -> 304.63991 | I46: =($C$23/(1+($C$17+0.01))^1+$D$23/(1+($C$17+0.01))^2+$E$23/(1+($C$17+0.01))^3+$F$23/(1+($C$17+0.01))^4+$G$23/(1+($C$17+0.01))^5+$H$23/(1+($C$17+0.01))^6+($H$23*(1+$B46)/(($C$17+0.01)-$B46))/(1+($C$17+0.01))^6-(Historicals!G216-Historicals!G225))/C38 -> 285.30102 | J46: =($C$23/(1+($C$17+0.015))^1+$D$23/(1+($C$17+0.015))^2+$E$23/(1+($C$17+0.015))^3+$F$23/(1+($C$17+0.015))^4+$G$23/(1+($C$17+0.015))^5+$H$23/(1+($C$17+0.015))^6+($H$23*(1+$B46)/(($C$17+0.015)-$B46))/(1+($C$17+0.015))^6-(Historicals!G216-Historicals!G225))/C38 -> 267.7748
B47: 0.035 | D47: =($C$23/(1+($C$17+-0.015))^1+$D$23/(1+($C$17+-0.015))^2+$E$23/(1+($C$17+-0.015))^3+$F$23/(1+($C$17+-0.015))^4+$G$23/(1+($C$17+-0.015))^5+$H$23/(1+($C$17+-0.015))^6+($H$23*(1+$B47)/(($C$17+-0.015)-$B47))/(1+($C$17+-0.015))^6-(Historicals!G216-Historicals!G225))/C38 -> 431.26025 | E47: =($C$23/(1+($C$17+-0.01))^1+$D$23/(1+($C$17+-0.01))^2+$E$23/(1+($C$17+-0.01))^3+$F$23/(1+($C$17+-0.01))^4+$G$23/(1+($C$17+-0.01))^5+$H$23/(1+($C$17+-0.01))^6+($H$23*(1+$B47)/(($C$17+-0.01)-$B47))/(1+($C$17+-0.01))^6-(Historicals!G216-Historicals!G225))/C38 -> 397.58923 | F47: =($C$23/(1+($C$17+-0.005))^1+$D$23/(1+($C$17+-0.005))^2+$E$23/(1+($C$17+-0.005))^3+$F$23/(1+($C$17+-0.005))^4+$G$23/(1+($C$17+-0.005))^5+$H$23/(1+($C$17+-0.005))^6+($H$23*(1+$B47)/(($C$17+-0.005)-$B47))/(1+($C$17+-0.005))^6-(Historicals!G216-Historicals!G225))/C38 -> 368.00258 | G47: =($C$23/(1+($C$17+0))^1+$D$23/(1+($C$17+0))^2+$E$23/(1+($C$17+0))^3+$F$23/(1+($C$17+0))^4+$G$23/(1+($C$17+0))^5+$H$23/(1+($C$17+0))^6+($H$23*(1+$B47)/(($C$17+0)-$B47))/(1+($C$17+0))^6-(Historicals!G216-Historicals!G225))/C38 -> 341.80401 | H47: =($C$23/(1+($C$17+0.005))^1+$D$23/(1+($C$17+0.005))^2+$E$23/(1+($C$17+0.005))^3+$F$23/(1+($C$17+0.005))^4+$G$23/(1+($C$17+0.005))^5+$H$23/(1+($C$17+0.005))^6+($H$23*(1+$B47)/(($C$17+0.005)-$B47))/(1+($C$17+0.005))^6-(Historicals!G216-Historicals!G225))/C38 -> 318.44685 | I47: =($C$23/(1+($C$17+0.01))^1+$D$23/(1+($C$17+0.01))^2+$E$23/(1+($C$17+0.01))^3+$F$23/(1+($C$17+0.01))^4+$G$23/(1+($C$17+0.01))^5+$H$23/(1+($C$17+0.01))^6+($H$23*(1+$B47)/(($C$17+0.01)-$B47))/(1+($C$17+0.01))^6-(Historicals!G216-Historicals!G225))/C38 -> 297.4959 | J47: =($C$23/(1+($C$17+0.015))^1+$D$23/(1+($C$17+0.015))^2+$E$23/(1+($C$17+0.015))^3+$F$23/(1+($C$17+0.015))^4+$G$23/(1+($C$17+0.015))^5+$H$23/(1+($C$17+0.015))^6+($H$23*(1+$B47)/(($C$17+0.015)-$B47))/(1+($C$17+0.015))^6-(Historicals!G216-Historicals!G225))/C38 -> 278.60043
B48: 0.04 | D48: =($C$23/(1+($C$17+-0.015))^1+$D$23/(1+($C$17+-0.015))^2+$E$23/(1+($C$17+-0.015))^3+$F$23/(1+($C$17+-0.015))^4+$G$23/(1+($C$17+-0.015))^5+$H$23/(1+($C$17+-0.015))^6+($H$23*(1+$B48)/(($C$17+-0.015)-$B48))/(1+($C$17+-0.015))^6-(Historicals!G216-Historicals!G225))/C38 -> 458.96458 | E48: =($C$23/(1+($C$17+-0.01))^1+$D$23/(1+($C$17+-0.01))^2+$E$23/(1+($C$17+-0.01))^3+$F$23/(1+($C$17+-0.01))^4+$G$23/(1+($C$17+-0.01))^5+$H$23/(1+($C$17+-0.01))^6+($H$23*(1+$B48)/(($C$17+-0.01)-$B48))/(1+($C$17+-0.01))^6-(Historicals!G216-Historicals!G225))/C38 -> 421.20783 | F48: =($C$23/(1+($C$17+-0.005))^1+$D$23/(1+($C$17+-0.005))^2+$E$23/(1+($C$17+-0.005))^3+$F$23/(1+($C$17+-0.005))^4+$G$23/(1+($C$17+-0.005))^5+$H$23/(1+($C$17+-0.005))^6+($H$23*(1+$B48)/(($C$17+-0.005)-$B48))/(1+($C$17+-0.005))^6-(Historicals!G216-Historicals!G225))/C38 -> 388.31803 | G48: =($C$23/(1+($C$17+0))^1+$D$23/(1+($C$17+0))^2+$E$23/(1+($C$17+0))^3+$F$23/(1+($C$17+0))^4+$G$23/(1+($C$17+0))^5+$H$23/(1+($C$17+0))^6+($H$23*(1+$B48)/(($C$17+0)-$B48))/(1+($C$17+0))^6-(Historicals!G216-Historicals!G225))/C38 -> 359.41576 | H48: =($C$23/(1+($C$17+0.005))^1+$D$23/(1+($C$17+0.005))^2+$E$23/(1+($C$17+0.005))^3+$F$23/(1+($C$17+0.005))^4+$G$23/(1+($C$17+0.005))^5+$H$23/(1+($C$17+0.005))^6+($H$23*(1+$B48)/(($C$17+0.005)-$B48))/(1+($C$17+0.005))^6-(Historicals!G216-Historicals!G225))/C38 -> 333.82126 | I48: =($C$23/(1+($C$17+0.01))^1+$D$23/(1+($C$17+0.01))^2+$E$23/(1+($C$17+0.01))^3+$F$23/(1+($C$17+0.01))^4+$G$23/(1+($C$17+0.01))^5+$H$23/(1+($C$17+0.01))^6+($H$23*(1+$B48)/(($C$17+0.01)-$B48))/(1+($C$17+0.01))^6-(Historicals!G216-Historicals!G225))/C38 -> 311.00087 | J48: =($C$23/(1+($C$17+0.015))^1+$D$23/(1+($C$17+0.015))^2+$E$23/(1+($C$17+0.015))^3+$F$23/(1+($C$17+0.015))^4+$G$23/(1+($C$17+0.015))^5+$H$23/(1+($C$17+0.015))^6+($H$23*(1+$B48)/(($C$17+0.015)-$B48))/(1+($C$17+0.015))^6-(Historicals!G216-Historicals!G225))/C38 -> 290.52977
B49: 0.045 | D49: =($C$23/(1+($C$17+-0.015))^1+$D$23/(1+($C$17+-0.015))^2+$E$23/(1+($C$17+-0.015))^3+$F$23/(1+($C$17+-0.015))^4+$G$23/(1+($C$17+-0.015))^5+$H$23/(1+($C$17+-0.015))^6+($H$23*(1+$B49)/(($C$17+-0.015)-$B49))/(1+($C$17+-0.015))^6-(Historicals!G216-Historicals!G225))/C38 -> 491.06059 | E49: =($C$23/(1+($C$17+-0.01))^1+$D$23/(1+($C$17+-0.01))^2+$E$23/(1+($C$17+-0.01))^3+$F$23/(1+($C$17+-0.01))^4+$G$23/(1+($C$17+-0.01))^5+$H$23/(1+($C$17+-0.01))^6+($H$23*(1+$B49)/(($C$17+-0.01)-$B49))/(1+($C$17+-0.01))^6-(Historicals!G216-Historicals!G225))/C38 -> 448.29548 | F49: =($C$23/(1+($C$17+-0.005))^1+$D$23/(1+($C$17+-0.005))^2+$E$23/(1+($C$17+-0.005))^3+$F$23/(1+($C$17+-0.005))^4+$G$23/(1+($C$17+-0.005))^5+$H$23/(1+($C$17+-0.005))^6+($H$23*(1+$B49)/(($C$17+-0.005)-$B49))/(1+($C$17+-0.005))^6-(Historicals!G216-Historicals!G225))/C38 -> 411.41323 | G49: =($C$23/(1+($C$17+0))^1+$D$23/(1+($C$17+0))^2+$E$23/(1+($C$17+0))^3+$F$23/(1+($C$17+0))^4+$G$23/(1+($C$17+0))^5+$H$23/(1+($C$17+0))^6+($H$23*(1+$B49)/(($C$17+0)-$B49))/(1+($C$17+0))^6-(Historicals!G216-Historicals!G225))/C38 -> 379.28299 | H49: =($C$23/(1+($C$17+0.005))^1+$D$23/(1+($C$17+0.005))^2+$E$23/(1+($C$17+0.005))^3+$F$23/(1+($C$17+0.005))^4+$G$23/(1+($C$17+0.005))^5+$H$23/(1+($C$17+0.005))^6+($H$23*(1+$B49)/(($C$17+0.005)-$B49))/(1+($C$17+0.005))^6-(Historicals!G216-Historicals!G225))/C38 -> 351.04614 | I49: =($C$23/(1+($C$17+0.01))^1+$D$23/(1+($C$17+0.01))^2+$E$23/(1+($C$17+0.01))^3+$F$23/(1+($C$17+0.01))^4+$G$23/(1+($C$17+0.01))^5+$H$23/(1+($C$17+0.01))^6+($H$23*(1+$B49)/(($C$17+0.01)-$B49))/(1+($C$17+0.01))^6-(Historicals!G216-Historicals!G225))/C38 -> 326.03905 | J49: =($C$23/(1+($C$17+0.015))^1+$D$23/(1+($C$17+0.015))^2+$E$23/(1+($C$17+0.015))^3+$F$23/(1+($C$17+0.015))^4+$G$23/(1+($C$17+0.015))^5+$H$23/(1+($C$17+0.015))^6+($H$23*(1+$B49)/(($C$17+0.015)-$B49))/(1+($C$17+0.015))^6-(Historicals!G216-Historicals!G225))/C38 -> 303.74069
...
