Workbook

Sheet Cover
B2: APOLLO HOSPITALS ENTERPRISE LIMITED
B3: 3-Statement Financial Model + SOTP Valuation
B4: Institutional Sell-Side Research | INR Millions | FY March Year-End
B7: Coverage: | C7: Apollo Hospitals Enterprise Ltd | NSE: APOLLOHOSP | BSE: 508869
B8: Model Currency: | C8: INR Millions (1 INR Mn = ₹10 Lakhs = ₹0.1 Crore)
B9: Shares Outstanding: | C9: 143.8 million (Equity Capital ₹719 Mn, Face Value ₹5)
B10: CMP (Reference): | C10: ₹7,636 (Apr 2026) | Market Cap: ~₹1,09,800 Crore
B11: Historical Period: | C11: FY2022A – FY2025A | Source: Annual Reports, MOSL Earnings Update May 2025
B12: Forecast Period: | C12: FY2026A – FY2030E | Conservative trend-based assumptions
B13: Last Updated: | C13: May 2026
B16: COLOR CODING CONVENTION
B17: ■ Blue Text | C17: Hard-coded inputs — historical data & assumptions
B18: ■ Black Text | C18: Calculated formulas and derived figures
B19: ■ Green Text | C19: Cross-sheet links (pulls from another worksheet)
B20: ■ Red Text | C20: External links to other files
B21: ■ Gray Italic | C21: Commentary, notes, and non-numeric labels
B24: MODEL NAVIGATION
B25: → Assumptions | C25: Central control panel — all growth rates, margins, capex & WC drivers
B26: → Hosp_Revenue | C26: Hospital revenue build: beds × occupancy × ARPOB
B27: → Hosp_Cost | C27: Hospital cost structure and segment EBITDA bridge
B28: → Inc_Statement | C28: Consolidated Income Statement (FY22A–FY30E)
B29: → Bal_Sheet | C29: Consolidated Balance Sheet (FY22A–FY30E)
B30: → Cash_Flow | C30: Consolidated Cash Flow Statement (FY22A–FY30E)
B31: → Hosp_Val | C31: Hospital valuation: EV/EBITDA + Forward P/E sensitivity
B32: → Pharmacy_Hlth | C32: Apollo Healthco (pharmacy + Apollo 24/7) — simple model & valuation
B33: → Diag_AHLL | C33: Apollo Health & Lifestyle Ltd — diagnostics + primary care
B34: → SOTP | C34: Sum-of-the-Parts: pre-demerger vs post-demerger implied valuation
B37: ⚠ DEMERGER NOTE: Apollo Hospitals is undertaking a composite scheme of arrangement (NCLT order: March 2026; shareholder vote: June 2026). The Healthco segment (pharmacy + Apollo 24|7) and Keimed will be demerged into a new listed entity (Apollo Healthtech Ltd / AHTL). AHEL retains the hospital business. The SOTP tab models both pre-demerger and post-demerger implied valuations.

Sheet Assumptions
B1: CENTRAL ASSUMPTIONS — Apollo Hospitals Enterprise Ltd | INR Millions
B2: Blue = hard-coded input | Black = formula | Historical FY22–FY25: actual reported | FY26–FY30: analyst assumptions
A3: Description | B3: INR Mn | C3: FY22A | D3: FY23A | E3: FY24A | F3: FY25A | G3: FY26A | H3: FY27E | I3: FY28E | J3: FY29E | K3: FY30E
B4: A. HOSPITAL REVENUE DRIVERS (India Owned Hospitals)
B5: Operating Beds (India owned, end of period) | C5: 6200 | D5: 6500 | E5: 6800 | F5: 7300 | G5: 7600 | H5: 8200 | I5: 8700 | J5: 9200 | K5: 9700
B6: Bed Additions (incremental) | G6: 400 | H6: 600 | I6: 500 | J6: 500 | K6: 500
B7: Bed Occupancy Rate (%) | C7: 0.64 | D7: 0.65 | E7: 0.66 | F7: 0.69 | G7: 0.68 | H7: 0.71 | I7: 0.72 | J7: 0.73 | K7: 0.73
B8: ARPOB — Avg Revenue Per Occupied Bed (INR/day) | C8: 50000 | D8: 52000 | E8: 57600 | F8: 60500 | G8: 67500 | H8: 67900 | I8: 71900 | J8: 75500 | K8: 79300
B9: ARPOB Growth Assumption (%) | D9: 0.04 | E9: 0.108 | F9: 0.051 | G9: 0.06 | H9: 0.06 | I9: 0.058 | J9: 0.05 | K9: 0.05
B10: Hospital Revenue — Bottoms-Up (INR Mn) | C10: =ROUND(C5*C7*C8*365/1000000,0) -> 72416 | D10: =ROUND(D5*D7*D8*365/1000000,0) -> 80191 | E10: =ROUND(E5*E7*E8*365/1000000,0) -> 94356 | F10: =ROUND(F5*F7*F8*365/1000000,0) -> 111230 | G10: =ROUND(G5*G7*G8*365/1000000,0) -> 127327 | H10: =ROUND(H5*H7*H8*365/1000000,0) -> 144290 | I10: =ROUND(I5*I7*I8*365/1000000,0) -> 164389 | J10: =ROUND(J5*J7*J8*365/1000000,0) -> 185076 | K10: =ROUND(K5*K7*K8*365/1000000,0) -> 204956
B11: Hospital Revenue YoY Growth (%) | D11: 0.088 | E11: 0.135 | F11: 0.13 | G11: 0.135 | H11: 0.145 | I11: 0.13 | J11: 0.12 | K11: 0.11
B12: B. SEGMENT REVENUE ASSUMPTIONS
B13: Healthco Revenue (pharmacy + Apollo 24/7) — INR Mn | C13: 53626 | D13: 67124 | E13: 78269 | F13: 90930 | G13: 108081 | H13: 125600 | I13: 144400 | J13: 164600 | K13: 184400
B14: Healthco Revenue Growth (%) | D14: 0.253 | E14: 0.166 | F14: 0.162 | G14: 0.18 | H14: 0.17 | I14: 0.15 | J14: 0.14 | K14: 0.12
B15: AHLL Revenue (diagnostics + primary care) — INR Mn | C15: 13000 | D15: 12000 | E15: 13653 | F15: 15535 | G15: 16703 | H15: 19660 | I15: 21820 | J15: 24000 | K15: 26400
B16: AHLL Revenue Growth (%) | D16: -0.077 | E16: 0.138 | F16: 0.138 | G16: 0.13 | H16: 0.12 | I16: 0.11 | J16: 0.1 | K16: 0.1
B17: Consolidated Revenue (check) — INR Mn | C17: =C10+C13+C15 -> 139042 | D17: =D10+D13+D15 -> 159315 | E17: =E10+E13+E15 -> 186278 | F17: =F10+F13+F15 -> 217695 | G17: =G10+G13+G15 -> 252111 | H17: =H10+H13+H15 -> 289550 | I17: =I10+I13+I15 -> 330609 | J17: =J10+J13+J15 -> 373676 | K17: =K10+K13+K15 -> 415756
B18: C. EBITDA MARGIN ASSUMPTIONS (Segment Level)
B19: Hospital EBITDA Margin — Implied from Cost Ratios (memo) | C19: 0.231 | D19: 0.228 | E19: 0.234 | F19: 0.241 | G19: =1-(G24+G25+G26+G27) -> 0.232 | H19: =1-(H24+H25+H26+H27) -> 0.245 | I19: =1-(I24+I25+I26+I27) -> 0.245 | J19: =1-(J24+J25+J26+J27) -> 0.245 | K19: =1-(K24+K25+K26+K27) -> 0.245
B20: Healthco EBITDA Margin (%) | C20: 0.005 | D20: 0.008 | E20: 0.01 | F20: 0.014 | G20: 0.088 | H20: 0.028 | I20: 0.038 | J20: 0.045 | K20: 0.05
B21: AHLL EBITDA Margin (%) | C21: 0.087 | D21: 0.093 | E21: 0.096 | F21: 0.107 | G21: 0.135 | H21: 0.125 | I21: 0.13 | J21: 0.135 | K21: 0.14
B22: Consolidated EBITDA Margin (%) — reported | C22: 0.149 | D22: 0.123 | E22: 0.125 | F22: 0.139 | G22: 0.141 | H22: 0.143 | I22: 0.145 | J22: 0.147 | K22: 0.148
B23: D. HOSPITAL COST STRUCTURE (% of Hospital Revenue)
B24: Employee Expenses (% of Hospital Revenue) | C24: 0.23 | D24: 0.235 | E24: 0.232 | F24: 0.228 | G24: 0.225 | H24: 0.226 | I24: 0.225 | J24: 0.224 | K24: 0.224
B25: Consumables & Materials (% of Hospital Revenue) | C25: 0.255 | D25: 0.262 | E25: 0.265 | F25: 0.268 | G25: 0.262 | H25: 0.266 | I25: 0.264 | J25: 0.263 | K25: 0.262
B26: Doctor Payouts (% of Hospital Revenue) | C26: 0.065 | D26: 0.068 | E26: 0.07 | F26: 0.072 | G26: 0.075 | H26: 0.073 | I26: 0.074 | J26: 0.075 | K26: 0.075
B27: Other Operating Expenses (% of Hospital Revenue) | C27: 0.22 | D27: 0.207 | E27: 0.199 | F27: 0.191 | G27: 0.206 | H27: 0.19 | I27: 0.192 | J27: 0.193 | K27: 0.194
B28: E. P&L BELOW-EBITDA ASSUMPTIONS
B29: Depreciation (INR Mn) | C29: 6007 | D29: 6152 | E29: 6870 | F29: 7575 | G29: 8761 | H29: 8900 | I29: 9500 | J29: 10000 | K29: 10500
B30: Interest & Finance Charges (INR Mn) | C30: 3786 | D30: 3808 | E30: 4494 | F30: 4585 | G30: 4496 | H30: 4200 | I30: 4000 | J30: 3800 | K30: 3600
B31: Other Income (INR Mn) | C31: 781 | D31: 903 | E31: 1063 | F31: 2003 | G31: 2676 | H31: 1600 | I31: 1700 | J31: 1800 | K31: 1900
B32: Effective Tax Rate (%) | C32: 0.302 | D32: 0.224 | E32: 0.327 | F32: 0.266 | G32: 0.247 | H32: 0.27 | I32: 0.27 | J32: 0.27 | K32: 0.27
B33: Minority Interest (INR Mn) | C33: 454 | D33: 687 | E33: 184 | F33: 262 | G33: 608 | H33: 300 | I33: 320 | J33: 340 | K33: 360
B34: F. CAPEX & WORKING CAPITAL
B35: Total Capex (INR Mn) | C35: 6518 | D35: 11285 | E35: 11349 | F35: 16978 | G35: 19620 | H35: 15000 | I35: 12000 | J35: 10000 | K35: 10000
B36: Debtor Days | C36: 44 | D36: 49 | E36: 48 | F36: 51 | G36: 50 | H36: 51 | I36: 50 | J36: 50 | K36: 50
B37: Inventory Days | C37: 11 | D37: 9 | E37: 9 | F37: 8 | G37: 8 | H37: 8 | I37: 8 | J37: 8 | K37: 8
B38: Payable Days | C38: 41 | D38: 42 | E38: 45 | F38: 38 | G38: 37 | H38: 40 | I38: 40 | J38: 40 | K38: 40
B39: G. VALUATION PARAMETERS
B40: Hospital EV/EBITDA — Base Case | C40: 28
...

Sheet Hosp_Revenue
B1: HOSPITAL REVENUE MODEL — Beds × Occupancy × ARPOB | INR Millions
B2: Source: Annual Reports, MOSL Earnings Update May 2025. Green cells = pull from Assumptions tab.
A3: Description | B3: INR Mn | C3: FY22A | D3: FY23A | E3: FY24A | F3: FY25A | G3: FY26A | H3: FY27E | I3: FY28E | J3: FY29E | K3: FY30E
B4: A. KEY OPERATING METRICS
B5: Operating Beds (India Owned, end of period) | C5: =Assumptions!C5 -> 6200 | D5: =Assumptions!D5 -> 6500 | E5: =Assumptions!E5 -> 6800 | F5: =Assumptions!F5 -> 7300 | G5: 7600 | H5: =Assumptions!H5 -> 8200 | I5: =Assumptions!I5 -> 8700 | J5: =Assumptions!J5 -> 9200 | K5: =Assumptions!K5 -> 9700
B6: Bed Occupancy Rate (%) | C6: =Assumptions!C7 -> 0.64 | D6: =Assumptions!D7 -> 0.65 | E6: =Assumptions!E7 -> 0.66 | F6: =Assumptions!F7 -> 0.69 | G6: 0.68 | H6: =Assumptions!H7 -> 0.71 | I6: =Assumptions!I7 -> 0.72 | J6: =Assumptions!J7 -> 0.73 | K6: =Assumptions!K7 -> 0.73
B7: ARPOB — Avg Revenue Per Occupied Bed (INR/day) | C7: =Assumptions!C8 -> 50000 | D7: =Assumptions!D8 -> 52000 | E7: =Assumptions!E8 -> 57600 | F7: =Assumptions!F8 -> 60500 | G7: 67500 | H7: =Assumptions!H8 -> 67900 | I7: =Assumptions!I8 -> 71900 | J7: =Assumptions!J8 -> 75500 | K7: =Assumptions!K8 -> 79300
B8: Occupied Bed Days (mn days/year) | C8: =ROUND(C5*C6*365/1000000,2) -> 1.45 | D8: =ROUND(D5*D6*365/1000000,2) -> 1.54 | E8: =ROUND(E5*E6*365/1000000,2) -> 1.64 | F8: =ROUND(F5*F6*365/1000000,2) -> 1.84 | G8: =ROUND(G5*G6*365/1000000,2) -> 1.89 | H8: =ROUND(H5*H6*365/1000000,2) -> 2.13 | I8: =ROUND(I5*I6*365/1000000,2) -> 2.29 | J8: =ROUND(J5*J6*365/1000000,2) -> 2.45 | K8: =ROUND(K5*K6*365/1000000,2) -> 2.58
B9: B. HOSPITAL REVENUE BUILD
B10: IP Revenue as % of Total Hospital Revenue | C10: 0.7 | D10: 0.7 | E10: 0.7 | F10: 0.7 | G10: 0.7 | H10: 0.7 | I10: 0.7 | J10: 0.7 | K10: 0.7
B11: Total Hospital Revenue — INR Mn (bottoms-up) | C11: =ROUND(C5*C6*C7*365/1000000,0) -> 72416 | D11: =ROUND(D5*D6*D7*365/1000000,0) -> 80191 | E11: =ROUND(E5*E6*E7*365/1000000,0) -> 94356 | F11: =ROUND(F5*F6*F7*365/1000000,0) -> 111230 | G11: =ROUND(G5*G6*G7*365/1000000,0) -> 127327 | H11: =ROUND(H5*H6*H7*365/1000000,0) -> 144290 | I11: =ROUND(I5*I6*I7*365/1000000,0) -> 164389 | J11: =ROUND(J5*J6*J7*365/1000000,0) -> 185076 | K11: =ROUND(K5*K6*K7*365/1000000,0) -> 204956
B12: Hospital Revenue — Reported / As Used in Model (INR Mn) | C12: 80000 | D12: 86800 | E12: 98636 | F12: 111475 | G12: =ROUND(G5*G6*G7*365/1000000,0) -> 127327 | H12: =Assumptions!H10 -> 144290 | I12: =Assumptions!I10 -> 164389 | J12: =Assumptions!J10 -> 185076 | K12: =Assumptions!K10 -> 204956
B13: YoY Revenue Growth (%) | D13: =IF(C12=0,"",D12/C12-1) -> 0.085 | E13: =IF(D12=0,"",E12/D12-1) -> 0.13635945 | F13: =IF(E12=0,"",F12/E12-1) -> 0.13016546 | G13: =IF(F12=0,"",G12/F12-1) -> 0.14220229 | H13: =IF(G12=0,"",H12/G12-1) -> 0.1332239 | I13: =IF(H12=0,"",I12/H12-1) -> 0.13929586 | J13: =IF(I12=0,"",J12/I12-1) -> 0.12584175 | K13: =IF(J12=0,"",K12/J12-1) -> 0.10741533
B14: C. ARPOB ANALYSIS
B15: ARPOB YoY Growth (%) | D15: =IF(C7=0,"",D7/C7-1) -> 0.04 | E15: =IF(D7=0,"",E7/D7-1) -> 0.10769231 | F15: =IF(E7=0,"",F7/E7-1) -> 0.050347222 | G15: =IF(F7=0,"",G7/F7-1) -> 0.11570248 | H15: =IF(G7=0,"",H7/G7-1) -> 0.0059259259 | I15: =IF(H7=0,"",I7/H7-1) -> 0.058910162 | J15: =IF(I7=0,"",J7/I7-1) -> 0.050069541 | K15: =IF(J7=0,"",K7/J7-1) -> 0.050331126
B16: Implied IP Revenue (ARPOB × Occ Bed Days) — INR Mn | C16: =ROUND(C8*C7*1000000/1000000,0) -> 72500 | D16: =ROUND(D8*D7*1000000/1000000,0) -> 80080 | E16: =ROUND(E8*E7*1000000/1000000,0) -> 94464 | F16: =ROUND(F8*F7*1000000/1000000,0) -> 111320 | G16: =ROUND(G8*G7*1000000/1000000,0) -> 127575 | H16: =ROUND(H8*H7*1000000/1000000,0) -> 144627 | I16: =ROUND(I8*I7*1000000/1000000,0) -> 164651 | J16: =ROUND(J8*J7*1000000/1000000,0) -> 184975 | K16: =ROUND(K8*K7*1000000/1000000,0) -> 204594
B17: IP Revenue as Reported (INR Mn) — memo | C17: 56000 | D17: 60800 | E17: 69000 | F17: 78000
B18: D. PEER ARPOB BENCHMARKS (FY25, reported)
B19: Apollo Hospitals — ARPOB (INR/day) | F19: 60500
B20: Max Healthcare — ARPOB (INR/day) | F20: 55000
B21: Fortis Healthcare — ARPOB (INR/day) | F21: 42000
B22: Narayana Hrudayalaya — ARPOB (INR/day) | F22: 28000
B24: NOTE ON BED COUNT: "Operating Beds" above = census beds used in ARPOB-based revenue model (~7,300 FY25A, ~7,600 FY26A). Apollo total network bed count (all facilities incl. managed, AHLL clinics) = 7,875 (FY24), ~8,000 (FY25), 8,131 (FY26; company reported). The two figures differ because ARPOB is calculated only on owned-operated census beds. FY26A bottoms-up check: 7,600 beds × 68% occ × ₹67,500/day × 365 = ₹127,340 Mn ≈ reported ₹127,501 Mn. ✓

Sheet Hosp_Cost
B1: HOSPITAL COST MODEL — Segment EBITDA Build | INR Millions
B2: Green = linked from Assumptions. Ratios = % of Hospital Revenue. Historical margins approximate from segment disclosures.
A3: Description | B3: INR Mn | C3: FY22A | D3: FY23A | E3: FY24A | F3: FY25A | G3: FY26A | H3: FY27E | I3: FY28E | J3: FY29E | K3: FY30E
B4: Hospital Revenue (INR Mn) | C4: =Hosp_Revenue!C12 -> 80000 | D4: =Hosp_Revenue!D12 -> 86800 | E4: =Hosp_Revenue!E12 -> 98636 | F4: =Hosp_Revenue!F12 -> 111475 | G4: =Hosp_Revenue!G12 -> 127327 | H4: =Hosp_Revenue!H12 -> 144290 | I4: =Hosp_Revenue!I12 -> 164389 | J4: =Hosp_Revenue!J12 -> 185076 | K4: =Hosp_Revenue!K12 -> 204956
B5: A. COST RATIOS (% of Hospital Revenue — Blue = input from Assumptions)
B6: Employee Expenses (% of Revenue) | C6: =Assumptions!C24 -> 0.23 | D6: =Assumptions!D24 -> 0.235 | E6: =Assumptions!E24 -> 0.232 | F6: =Assumptions!F24 -> 0.228 | G6: =Assumptions!G24 -> 0.225 | H6: =Assumptions!H24 -> 0.226 | I6: =Assumptions!I24 -> 0.225 | J6: =Assumptions!J24 -> 0.224 | K6: =Assumptions!K24 -> 0.224
B7: Consumables & Materials (% of Revenue) | C7: =Assumptions!C25 -> 0.255 | D7: =Assumptions!D25 -> 0.262 | E7: =Assumptions!E25 -> 0.265 | F7: =Assumptions!F25 -> 0.268 | G7: =Assumptions!G25 -> 0.262 | H7: =Assumptions!H25 -> 0.266 | I7: =Assumptions!I25 -> 0.264 | J7: =Assumptions!J25 -> 0.263 | K7: =Assumptions!K25 -> 0.262
B8: Doctor Payouts (% of Revenue) | C8: =Assumptions!C26 -> 0.065 | D8: =Assumptions!D26 -> 0.068 | E8: =Assumptions!E26 -> 0.07 | F8: =Assumptions!F26 -> 0.072 | G8: =Assumptions!G26 -> 0.075 | H8: =Assumptions!H26 -> 0.073 | I8: =Assumptions!I26 -> 0.074 | J8: =Assumptions!J26 -> 0.075 | K8: =Assumptions!K26 -> 0.075
B9: Other Operating Expenses (% of Revenue) | C9: =Assumptions!C27 -> 0.22 | D9: =Assumptions!D27 -> 0.207 | E9: =Assumptions!E27 -> 0.199 | F9: =Assumptions!F27 -> 0.191 | G9: =Assumptions!G27 -> 0.206 | H9: =Assumptions!H27 -> 0.19 | I9: =Assumptions!I27 -> 0.192 | J9: =Assumptions!J27 -> 0.193 | K9: =Assumptions!K27 -> 0.194
B10: Total Cost Ratio (% of Revenue) | C10: =C6+C7+C8+C9 -> 0.77 | D10: =D6+D7+D8+D9 -> 0.772 | E10: =E6+E7+E8+E9 -> 0.766 | F10: =F6+F7+F8+F9 -> 0.759 | G10: =G6+G7+G8+G9 -> 0.768 | H10: =H6+H7+H8+H9 -> 0.755 | I10: =I6+I7+I8+I9 -> 0.755 | J10: =J6+J7+J8+J9 -> 0.755 | K10: =K6+K7+K8+K9 -> 0.755
B11: B. ABSOLUTE COST VALUES (INR Mn)
B12: Employee Expenses (INR Mn) | C12: =ROUND(C4*C6,0) -> 18400 | D12: =ROUND(D4*D6,0) -> 20398 | E12: =ROUND(E4*E6,0) -> 22884 | F12: =ROUND(F4*F6,0) -> 25416 | G12: =ROUND(G4*G6,0) -> 28649 | H12: =ROUND(H4*H6,0) -> 32610 | I12: =ROUND(I4*I6,0) -> 36988 | J12: =ROUND(J4*J6,0) -> 41457 | K12: =ROUND(K4*K6,0) -> 45910
B13: Consumables & Materials (INR Mn) | C13: =ROUND(C4*C7,0) -> 20400 | D13: =ROUND(D4*D7,0) -> 22742 | E13: =ROUND(E4*E7,0) -> 26139 | F13: =ROUND(F4*F7,0) -> 29875 | G13: =ROUND(G4*G7,0) -> 33360 | H13: =ROUND(H4*H7,0) -> 38381 | I13: =ROUND(I4*I7,0) -> 43399 | J13: =ROUND(J4*J7,0) -> 48675 | K13: =ROUND(K4*K7,0) -> 53698
B14: Doctor Payouts (INR Mn) | C14: =ROUND(C4*C8,0) -> 5200 | D14: =ROUND(D4*D8,0) -> 5902 | E14: =ROUND(E4*E8,0) -> 6905 | F14: =ROUND(F4*F8,0) -> 8026 | G14: =ROUND(G4*G8,0) -> 9550 | H14: =ROUND(H4*H8,0) -> 10533 | I14: =ROUND(I4*I8,0) -> 12165 | J14: =ROUND(J4*J8,0) -> 13881 | K14: =ROUND(K4*K8,0) -> 15372
B15: Other Operating Expenses (INR Mn) | C15: =ROUND(C4*C9,0) -> 17600 | D15: =ROUND(D4*D9,0) -> 17968 | E15: =ROUND(E4*E9,0) -> 19629 | F15: =ROUND(F4*F9,0) -> 21292 | G15: =ROUND(G4*G9,0) -> 26229 | H15: =ROUND(H4*H9,0) -> 27415 | I15: =ROUND(I4*I9,0) -> 31563 | J15: =ROUND(J4*J9,0) -> 35720 | K15: =ROUND(K4*K9,0) -> 39761
B16: Total Hospital Operating Costs (INR Mn) | C16: =C12+C13+C14+C15 -> 61600 | D16: =D12+D13+D14+D15 -> 67010 | E16: =E12+E13+E14+E15 -> 75557 | F16: =F12+F13+F14+F15 -> 84609 | G16: =G12+G13+G14+G15 -> 97788 | H16: =H12+H13+H14+H15 -> 108939 | I16: =I12+I13+I14+I15 -> 124115 | J16: =J12+J13+J14+J15 -> 139733 | K16: =K12+K13+K14+K15 -> 154741
B17: C. HOSPITAL SEGMENT EBITDA
B18: Hospital EBITDA (INR Mn) | C18: =C4-C16 -> 18400 | D18: =D4-D16 -> 19790 | E18: =E4-E16 -> 23079 | F18: =F4-F16 -> 26866 | G18: =G4-G16 -> 29539 | H18: =H4-H16 -> 35351 | I18: =I4-I16 -> 40274 | J18: =J4-J16 -> 45343 | K18: =K4-K16 -> 50215
B19: Hospital EBITDA Margin (%) | C19: =IF(C4=0,"",C18/C4) -> 0.23 | D19: =IF(D4=0,"",D18/D4) -> 0.22799539 | E19: =IF(E4=0,"",E18/E4) -> 0.23398151 | F19: =IF(F4=0,"",F18/F4) -> 0.24100471 | G19: =IF(G4=0,"",G18/G4) -> 0.23199321 | H19: =IF(H4=0,"",H18/H4) -> 0.24499965 | I19: =IF(I4=0,"",I18/I4) -> 0.24499206 | J19: =IF(J4=0,"",J18/J4) -> 0.24499665 | K19: =IF(K4=0,"",K18/K4) -> 0.24500381
B20: Hospital EBITDA Margin — Assumptions Input (%) | C20: =Assumptions!C19 -> 0.231 | D20: =Assumptions!D19 -> 0.228 | E20: =Assumptions!E19 -> 0.234 | F20: =Assumptions!F19 -> 0.241 | G20: =Assumptions!G19 -> 0.232 | H20: =Assumptions!H19 -> 0.245 | I20: =Assumptions!I19 -> 0.245 | J20: =Assumptions!J19 -> 0.245 | K20: =Assumptions!K19 -> 0.245

Sheet Inc_Statement
B1: CONSOLIDATED INCOME STATEMENT | Apollo Hospitals Enterprise Ltd | INR Millions
B2: FY ends March. Historical: Annual Report / MOSL May 2025. Forecasts: analyst estimates linked from Assumptions.
A3: Description | B3: INR Mn | C3: FY22A | D3: FY23A | E3: FY24A | F3: FY25A | G3: FY26A | H3: FY27E | I3: FY28E | J3: FY29E | K3: FY30E
B4: A. REVENUE BY SEGMENT (INR Mn)
B5: Healthcare Services (Hospitals) | C5: 80000 | D5: 86800 | E5: 98636 | F5: 111475 | G5: 127501 | H5: =Assumptions!H10 -> 144290 | I5: =Assumptions!I10 -> 164389 | J5: =Assumptions!J10 -> 185076 | K5: =Assumptions!K10 -> 204956
B6: Apollo Healthco (Pharmacy + Apollo 24/7) | C6: 53626 | D6: 67124 | E6: 78269 | F6: 90930 | G6: 108081 | H6: =Assumptions!H13 -> 125600 | I6: =Assumptions!I13 -> 144400 | J6: =Assumptions!J13 -> 164600 | K6: =Assumptions!K13 -> 184400
B7: Apollo Health & Lifestyle (Diagnostics + Primary Care) | C7: 13000 | D7: 12200 | E7: 13653 | F7: 15535 | G7: 16703 | H7: =Assumptions!H15 -> 19660 | I7: =Assumptions!I15 -> 21820 | J7: =Assumptions!J15 -> 24000 | K7: =Assumptions!K15 -> 26400
B8: Total Revenue | C8: 146626 | D8: 166124 | E8: 190558 | F8: 217940 | G8: 252285 | H8: =H5+H6+H7 -> 289550 | I8: =I5+I6+I7 -> 330609 | J8: =J5+J6+J7 -> 373676 | K8: =K5+K6+K7 -> 415756
B9: Revenue Growth (%) | D9: =IF(D8=0,"",D8/C8-1) -> 0.13297778 | E9: =IF(E8=0,"",E8/D8-1) -> 0.1470829 | F9: =IF(F8=0,"",F8/E8-1) -> 0.14369378 | G9: =IF(G8=0,"",G8/F8-1) -> 0.15758924 | H9: =IF(G8=0,"",H8/G8-1) -> 0.14770993 | I9: =IF(H8=0,"",I8/H8-1) -> 0.1418028 | J9: =IF(I8=0,"",J8/I8-1) -> 0.13026566 | K9: =IF(J8=0,"",K8/J8-1) -> 0.11261092
B10: B. EBITDA BRIDGE (INR Mn)
B11: Hospital EBITDA | C11: 20452 | D11: 18843 | E11: 21813 | F11: 27283 | G11: 29580 | H11: =Hosp_Cost!H18 -> 35351 | I11: =Hosp_Cost!I18 -> 40274 | J11: =Hosp_Cost!J18 -> 45343 | K11: =Hosp_Cost!K18 -> 50215
B12: Healthco EBITDA | C12: 268 | D12: 537 | E12: 783 | F12: 1273 | G12: 9511 | H12: =ROUND(H6*Assumptions!H20,0) -> 3517 | I12: =ROUND(I6*Assumptions!I20,0) -> 5487 | J12: =ROUND(J6*Assumptions!J20,0) -> 7407 | K12: =ROUND(K6*Assumptions!K20,0) -> 9220
B13: AHLL EBITDA | C13: 1131 | D13: 1116 | E13: 1311 | F13: 1662 | G13: 2255 | H13: =ROUND(H7*Assumptions!H21,0) -> 2458 | I13: =ROUND(I7*Assumptions!I21,0) -> 2837 | J13: =ROUND(J7*Assumptions!J21,0) -> 3240 | K13: =ROUND(K7*Assumptions!K21,0) -> 3696
B14: Corp / Eliminations / Unallocated | C14: 0 | D14: 0 | E14: 0 | F14: 0 | G14: -3656 | H14: -1500 | I14: -1500 | J14: -1500 | K14: -1500
B15: EBITDA | C15: 21851 | D15: 20496 | E15: 23907 | F15: 30218 | G15: 37690 | H15: =H11+H12+H13+H14 -> 39826 | I15: =I11+I12+I13+I14 -> 47098 | J15: =J11+J12+J13+J14 -> 54490 | K15: =K11+K12+K13+K14 -> 61631
B16: EBITDA Margin (%) | C16: =IF(C8=0,"",C15/C8) -> 0.14902541 | D16: =IF(D8=0,"",D15/D8) -> 0.12337772 | E16: =IF(E8=0,"",E15/E8) -> 0.12545787 | F16: =IF(F8=0,"",F15/F8) -> 0.13865284 | G16: =IF(G8=0,"",G15/G8) -> 0.14939453 | H16: =IF(H8=0,"",H15/H8) -> 0.13754447 | I16: =IF(I8=0,"",I15/I8) -> 0.14245831 | J16: =IF(J8=0,"",J15/J8) -> 0.14582151 | K16: =IF(K8=0,"",K15/K8) -> 0.14823839
B17: C. P&L BELOW EBITDA (INR Mn)
B18: Less: Depreciation & Amortisation | C18: 6007 | D18: 6152 | E18: 6870 | F18: 7575 | G18: 8761 | H18: =Assumptions!H29 -> 8900 | I18: =Assumptions!I29 -> 9500 | J18: =Assumptions!J29 -> 10000 | K18: =Assumptions!K29 -> 10500
B19: EBIT | C19: 15844 | D19: 14344 | E19: 17037 | F19: 22643 | G19: 28929 | H19: =H15-H18 -> 30926 | I19: =I15-I18 -> 37598 | J19: =J15-J18 -> 44490 | K19: =K15-K18 -> 51131
B20: EBIT Margin (%) | C20: =IF(C8=0,"",C19/C8) -> 0.10805723 | D20: =IF(D8=0,"",D19/D8) -> 0.08634514 | E20: =IF(E8=0,"",E19/E8) -> 0.08940585 | F20: =IF(F8=0,"",F19/F8) -> 0.10389557 | G20: =IF(G8=0,"",G19/G8) -> 0.11466794 | H20: =IF(H8=0,"",H19/H8) -> 0.10680711 | I20: =IF(I8=0,"",I19/I8) -> 0.11372346 | J20: =IF(J8=0,"",J19/J8) -> 0.11906036 | K20: =IF(K8=0,"",K19/K8) -> 0.12298319
B21: Less: Interest & Finance Charges | C21: 3786 | D21: 3808 | E21: 4494 | F21: 4585 | G21: 4496 | H21: =Assumptions!H30 -> 4200 | I21: =Assumptions!I30 -> 4000 | J21: =Assumptions!J30 -> 3800 | K21: =Assumptions!K30 -> 3600
B22: Add: Other Income | C22: 781 | D22: 903 | E22: 1063 | F22: 2003 | G22: 2676 | H22: =Assumptions!H31 -> 1600 | I22: =Assumptions!I31 -> 1700 | J22: =Assumptions!J31 -> 1800 | K22: =Assumptions!K31 -> 1900
B23: Profit Before Tax (PBT) | C23: 15781 | D23: 11439 | E23: 13625 | F23: 20061 | G23: 26609 | H23: =H19-H21+H22 -> 28326 | I23: =I19-I21+I22 -> 35298 | J23: =J19-J21+J22 -> 42490 | K23: =K19-K21+K22 -> 49431
B24: Less: Tax | C24: 4770 | D24: 2562 | E24: 4455 | F24: 5340 | G24: 6582 | H24: =ROUND(MAX(H23,0)*Assumptions!H32,0) -> 7648 | I24: =ROUND(MAX(I23,0)*Assumptions!I32,0) -> 9530 | J24: =ROUND(MAX(J23,0)*Assumptions!J32,0) -> 11472 | K24: =ROUND(MAX(K23,0)*Assumptions!K32,0) -> 13346
B25: Less: Minority Interest | C25: 454 | D25: 687 | E25: 184 | F25: 262 | G25: 608 | H25: =Assumptions!H33 -> 300 | I25: =Assumptions!I33 -> 320 | J25: =Assumptions!J33 -> 340 | K25: =Assumptions!K33 -> 360
B26: Profit After Tax (PAT) — Reported | C26: 10557 | D26: 8190 | E26: 8986 | F26: 14459 | G26: 19419 | H26: =H23-H24-H25 -> 20378 | I26: =I23-I24-I25 -> 25448 | J26: =J23-J24-J25 -> 30678 | K26: =K23-K24-K25 -> 35725
B27: PAT Margin (%) | C27: =IF(C8=0,"",C26/C8) -> 0.071999509 | D27: =IF(D8=0,"",D26/D8) -> 0.049300523 | E27: =IF(E8=0,"",E26/E8) -> 0.047156246 | F27: =IF(F8=0,"",F26/F8) -> 0.066343948 | G27: =IF(G8=0,"",G26/G8) -> 0.076972472 | H27: =IF(H8=0,"",H26/H8) -> 0.070378173 | I27: =IF(I8=0,"",I26/I8) -> 0.076973101 | J27: =IF(J8=0,"",J26/J8) -> 0.08209786 | K27: =IF(K8=0,"",K26/K8) -> 0.085927804
B28: EPS (INR) — Diluted | C28: 73.41 | D28: 56.95 | E28: 62.49 | F28: 100.55 | G28: 135.04 | H28: =IF(H26=0,"",H26/143.8) -> 141.71071 | I28: =IF(I26=0,"",I26/143.8) -> 176.96801 | J28: =IF(J26=0,"",J26/143.8) -> 213.33797 | K28: =IF(K26=0,"",K26/143.8) -> 248.43533
B29: EPS — Reported Historical (INR) | C29: 68.1 | D29: 48.2 | E29: 62.4 | F29: 100.6

Sheet Bal_Sheet
B1: CONSOLIDATED BALANCE SHEET | Apollo Hospitals Enterprise Ltd | INR Millions
B2: Historical: Annual Report / MOSL. Forecasts: driven by capex, D&A, WC assumptions. Lease liabilities shown separately per Ind AS 116.
A3: Description | B3: INR Mn | C3: FY22A | D3: FY23A | E3: FY24A | F3: FY25A | G3: FY26A | H3: FY27E | I3: FY28E | J3: FY29E | K3: FY30E
B4: EQUITY & LIABILITIES
B5: Equity Share Capital | C5: 719 | D5: 719 | E5: 719 | F5: 719 | G5: 719 | H5: 719 | I5: 719 | J5: 719 | K5: 719
B6: Reserves & Surplus | C6: 55733 | D6: 61253 | E6: 68635 | F6: 81404 | G6: 99026 | H6: =G6+Inc_Statement!H26-720 -> 118684 | I6: =H6+Inc_Statement!I26-720 -> 143412 | J6: =I6+Inc_Statement!J26-720 -> 173370 | K6: =J6+Inc_Statement!K26-720 -> 208375
B7: Net Worth (Equity + Reserves) | C7: =C5+C6 -> 56452 | D7: =D5+D6 -> 61972 | E7: =E5+E6 -> 69354 | F7: =F5+F6 -> 82123 | G7: 99745 | H7: =H5+H6 -> 119403 | I7: =I5+I6 -> 144131 | J7: =J5+J6 -> 174089 | K7: =K5+K6 -> 209094
B8: Minority Interest | C8: 2543 | D8: 3341 | E8: 3851 | F8: 4406 | G8: 4406 | H8: 4406 | I8: 4406 | J8: 4406 | K8: 4406
B9: Total Borrowings (Bank Debt) | C9: 26357 | D9: 27103 | E9: 31619 | F9: 52752 | G9: 56585 | H9: 43000 | I9: 38000 | J9: 34000 | K9: 30000
B10: Lease Liabilities (Ind AS 116) | C10: 13333 | D10: 14983 | E10: 19814 | F10: 24139 | G10: 25000 | H10: 25000 | I10: 25500 | J10: 26000 | K10: 26500
B11: Deferred Tax & Other LT Liabilities | C11: 7762 | D11: 8589 | E11: 8863 | F11: 9017 | G11: 9500 | H11: 9400 | I11: 9600 | J11: 9800 | K11: 10000
B12: TOTAL EQUITY & LIABILITIES | C12: =C7+C8+C9+C10+C11 -> 106447 | D12: =D7+D8+D9+D10+D11 -> 115988 | E12: =E7+E8+E9+E10+E11 -> 133501 | F12: =F7+F8+F9+F10+F11 -> 172437 | G12: =G7+G8+G9+G10+G11 -> 195236 | H12: =H7+H8+H9+H10+H11 -> 201209 | I12: =I7+I8+I9+I10+I11 -> 221637 | J12: =J7+J8+J9+J10+J11 -> 248295 | K12: =K7+K8+K9+K10+K11 -> 280000
B13: ASSETS
B14: Net Fixed Assets (incl. ROU) | C14: 73413 | D14: 75298 | E14: 86763 | F14: 101049 | G14: 109000 | H14: =G14+Assumptions!H35-Assumptions!H29 -> 115100 | I14: =H14+Assumptions!I35-Assumptions!I29 -> 117600 | J14: =I14+Assumptions!J35-Assumptions!J29 -> 117600 | K14: =J14+Assumptions!K35-Assumptions!K29 -> 117100
B15: Capital Work-in-Progress | C15: 455 | D15: 6098 | E15: 8447 | F15: 7710 | G15: 9915 | H15: 3500 | I15: 3000 | J15: 3000 | K15: 3000
B16: Goodwill & Intangibles | C16: 9235 | D16: 9858 | E16: 10123 | F16: 10305 | G16: 10305 | H16: 10305 | I16: 10305 | J16: 10305 | K16: 10305
B17: Investments (LT + Current) | C17: 8063 | D17: 5777 | E17: 9895 | F17: 24896 | G17: 25000 | H17: 18000 | I17: 16000 | J17: 14000 | K17: 12000
B18: Trade Receivables | C18: 17676 | D18: 22342 | E18: 25149 | F18: 30161 | G18: 34849 | H18: =ROUND(Inc_Statement!H8*Assumptions!H36/365,0) -> 40458 | I18: =ROUND(Inc_Statement!I8*Assumptions!I36/365,0) -> 45289 | J18: =ROUND(Inc_Statement!J8*Assumptions!J36/365,0) -> 51188 | K18: =ROUND(Inc_Statement!K8*Assumptions!K36/365,0) -> 56953
B19: Inventories | C19: 4318 | D19: 3902 | E19: 4598 | F19: 4808 | G19: 5200 | H19: =ROUND(Inc_Statement!H8*Assumptions!H37/365,0) -> 6346 | I19: =ROUND(Inc_Statement!I8*Assumptions!I37/365,0) -> 7246 | J19: =ROUND(Inc_Statement!J8*Assumptions!J37/365,0) -> 8190 | K19: =ROUND(Inc_Statement!K8*Assumptions!K37/365,0) -> 9112
B20: Cash & Bank Balances | C20: 10359 | D20: 7758 | E20: 9338 | F20: 13602 | G20: 21333 | H20: 14000 | I20: 16500 | J20: 19000 | K20: 22000
B21: Other Current Assets & Loans | C21: 8541 | D21: 13123 | E21: 13109 | F21: 13912 | G21: 17000 | H21: 15000 | I21: 15500 | J21: 16000 | K21: 16500
B22: Less: Trade Payables | C22: 16318 | D22: 19157 | E22: 23686 | F22: 22405 | G22: 25500 | H22: =ROUND(Inc_Statement!H8*Assumptions!H38/365,0) -> 31732 | I22: =ROUND(Inc_Statement!I8*Assumptions!I38/365,0) -> 36231 | J22: =ROUND(Inc_Statement!J8*Assumptions!J38/365,0) -> 40951 | K22: =ROUND(Inc_Statement!K8*Assumptions!K38/365,0) -> 45562
B23: Less: Other Current Liabilities & Provisions | C23: 11841 | D23: 13298 | E23: 14709 | F23: 16169 | G23: 16400 | H23: 18000 | I23: 18500 | J23: 19000 | K23: 19500
B24: TOTAL ASSETS | C24: =C14+C15+C16+C17+C18+C19+C20+C21-C22-C23 -> 103901 | D24: =D14+D15+D16+D17+D18+D19+D20+D21-D22-D23 -> 111701 | E24: =E14+E15+E16+E17+E18+E19+E20+E21-E22-E23 -> 129027 | F24: =F14+F15+F16+F17+F18+F19+F20+F21-F22-F23 -> 167869 | G24: =G14+G15+G16+G17+G18+G19+G20+G21 -> 232602 | H24: =H14+H15+H16+H17+H18+H19+H20+H21-H22-H23 -> 172977 | I24: =I14+I15+I16+I17+I18+I19+I20+I21-I22-I23 -> 176709 | J24: =J14+J15+J16+J17+J18+J19+J20+J21-J22-J23 -> 179332 | K24: =K14+K15+K16+K17+K18+K19+K20+K21-K22-K23 -> 181908
B26: WORKING CAPITAL ANALYSIS (clearly itemised)
A27: Description | B27: INR Mn | C27: FY22A | D27: FY23A | E27: FY24A | F27: FY25A | G27: FY26A | H27: FY27E | I27: FY28E | J27: FY29E | K27: FY30E
B28: GROSS CURRENT ASSETS
B29: Cash & Bank Balances | C29: =Bal_Sheet!C20 -> 10359 | D29: =Bal_Sheet!D20 -> 7758 | E29: =Bal_Sheet!E20 -> 9338 | F29: =Bal_Sheet!F20 -> 13602 | G29: =Bal_Sheet!G20 -> 21333 | H29: =Bal_Sheet!H20 -> 14000 | I29: =Bal_Sheet!I20 -> 16500 | J29: =Bal_Sheet!J20 -> 19000 | K29: =Bal_Sheet!K20 -> 22000
B30: Trade Receivables | C30: =Bal_Sheet!C18 -> 17676 | D30: =Bal_Sheet!D18 -> 22342 | E30: =Bal_Sheet!E18 -> 25149 | F30: =Bal_Sheet!F18 -> 30161 | G30: =Bal_Sheet!G18 -> 34849 | H30: =Bal_Sheet!H18 -> 40458 | I30: =Bal_Sheet!I18 -> 45289 | J30: =Bal_Sheet!J18 -> 51188 | K30: =Bal_Sheet!K18 -> 56953
B31: Inventories | C31: =Bal_Sheet!C19 -> 4318 | D31: =Bal_Sheet!D19 -> 3902 | E31: =Bal_Sheet!E19 -> 4598 | F31: =Bal_Sheet!F19 -> 4808 | G31: =Bal_Sheet!G19 -> 5200 | H31: =Bal_Sheet!H19 -> 6346 | I31: =Bal_Sheet!I19 -> 7246 | J31: =Bal_Sheet!J19 -> 8190 | K31: =Bal_Sheet!K19 -> 9112
B32: Other Current Assets & Loans | C32: =Bal_Sheet!C21 -> 8541 | D32: =Bal_Sheet!D21 -> 13123 | E32: =Bal_Sheet!E21 -> 13109 | F32: =Bal_Sheet!F21 -> 13912 | G32: =Bal_Sheet!G21 -> 17000 | H32: =Bal_Sheet!H21 -> 15000 | I32: =Bal_Sheet!I21 -> 15500 | J32: =Bal_Sheet!J21 -> 16000 | K32: =Bal_Sheet!K21 -> 16500
B33: Total Gross Current Assets | C33: =C29+C30+C31+C32 -> 40894 | D33: =D29+D30+D31+D32 -> 47125 | E33: =E29+E30+E31+E32 -> 52194 | F33: =F29+F30+F31+F32 -> 62483 | G33: =G29+G30+G31+G32 -> 78382 | H33: =H29+H30+H31+H32 -> 75804 | I33: =I29+I30+I31+I32 -> 84535 | J33: =J29+J30+J31+J32 -> 94378 | K33: =K29+K30+K31+K32 -> 104565
B34: GROSS CURRENT LIABILITIES
B35: Trade Payables | C35: =Bal_Sheet!C22 -> 16318 | D35: =Bal_Sheet!D22 -> 19157 | E35: =Bal_Sheet!E22 -> 23686 | F35: =Bal_Sheet!F22 -> 22405 | G35: =Bal_Sheet!G22 -> 25500 | H35: =Bal_Sheet!H22 -> 31732 | I35: =Bal_Sheet!I22 -> 36231 | J35: =Bal_Sheet!J22 -> 40951 | K35: =Bal_Sheet!K22 -> 45562
B36: Other Current Liabilities & Provisions | C36: =Bal_Sheet!C23 -> 11841 | D36: =Bal_Sheet!D23 -> 13298 | E36: =Bal_Sheet!E23 -> 14709 | F36: =Bal_Sheet!F23 -> 16169 | G36: =Bal_Sheet!G23 -> 16400 | H36: =Bal_Sheet!H23 -> 18000 | I36: =Bal_Sheet!I23 -> 18500 | J36: =Bal_Sheet!J23 -> 19000 | K36: =Bal_Sheet!K23 -> 19500
B37: Total Gross Current Liabilities | C37: =C35+C36 -> 28159 | D37: =D35+D36 -> 32455 | E37: =E35+E36 -> 38395 | F37: =F35+F36 -> 38574 | G37: =G35+G36 -> 41900 | H37: =H35+H36 -> 49732 | I37: =I35+I36 -> 54731 | J37: =J35+J36 -> 59951 | K37: =K35+K36 -> 65062
B38: Net Working Capital (ex-Cash = Recv+Inv–Pay–OtherCL) | C38: =Bal_Sheet!C18+Bal_Sheet!C19-Bal_Sheet!C22-Bal_Sheet!C23 -> -6165 | D38: =Bal_Sheet!D18+Bal_Sheet!D19-Bal_Sheet!D22-Bal_Sheet!D23 -> -6211 | E38: =Bal_Sheet!E18+Bal_Sheet!E19-Bal_Sheet!E22-Bal_Sheet!E23 -> -8648 | F38: =Bal_Sheet!F18+Bal_Sheet!F19-Bal_Sheet!F22-Bal_Sheet!F23 -> -3605 | G38: =Bal_Sheet!G18+Bal_Sheet!G19-Bal_Sheet!G22-Bal_Sheet!G23 -> -1851 | H38: =Bal_Sheet!H18+Bal_Sheet!H19-Bal_Sheet!H22-Bal_Sheet!H23 -> -2928 | I38: =Bal_Sheet!I18+Bal_Sheet!I19-Bal_Sheet!I22-Bal_Sheet!I23 -> -2196 | J38: =Bal_Sheet!J18+Bal_Sheet!J19-Bal_Sheet!J22-Bal_Sheet!J23 -> -573 | K38: =Bal_Sheet!K18+Bal_Sheet!K19-Bal_Sheet!K22-Bal_Sheet!K23 -> 1003
B39: Net Working Capital (incl. Cash) | C39: =C33-C37 -> 12735 | D39: =D33-D37 -> 14670 | E39: =E33-E37 -> 13799 | F39: =F33-F37 -> 23909 | G39: =G33-G37 -> 36482 | H39: =H33-H37 -> 26072 | I39: =I33-I37 -> 29804 | J39: =J33-J37 -> 34427 | K39: =K33-K37 -> 39503
B40: NWC as % of Revenue (ex-cash) | C40: =IF(Inc_Statement!C8=0,"",C38/Inc_Statement!C8) -> -0.042045749 | D40: =IF(Inc_Statement!D8=0,"",D38/Inc_Statement!D8) -> -0.037387734 | E40: =IF(Inc_Statement!E8=0,"",E38/Inc_Statement!E8) -> -0.045382508 | F40: =IF(Inc_Statement!F8=0,"",F38/Inc_Statement!F8) -> -0.01654125 | G40: =IF(Inc_Statement!G8=0,"",G38/Inc_Statement!G8) -> -0.0073369404 | H40: =IF(Inc_Statement!H8=0,"",H38/Inc_Statement!H8) -> -0.010112243 | I40: =IF(Inc_Statement!I8=0,"",I38/Inc_Statement!I8) -> -0.0066422874 | J40: =IF(Inc_Statement!J8=0,"",J38/Inc_Statement!J8) -> -0.001533414 | K40: =IF(Inc_Statement!K8=0,"",K38/Inc_Statement!K8) -> 0.0024124727
B41: Note: WC rows above pull directly from BS items. Positive NWC = net asset position. Apollo's pharmacy segment typically shows negative NWC (favourable). Cash excluded from NWC for operational clarity.

Sheet Cash_Flow
B1: CONSOLIDATED CASH FLOW STATEMENT | Apollo Hospitals Enterprise Ltd | INR Millions
B2: Historical: Annual Report / MOSL. Green = cross-sheet links. FCF = CFO minus Capex.
A3: Description | B3: INR Mn | C3: FY22A | D3: FY23A | E3: FY24A | F3: FY25A | G3: FY26A | H3: FY27E | I3: FY28E | J3: FY29E | K3: FY30E
B4: A. CASH FROM OPERATIONS (INR Mn)
B5: Profit After Tax | C5: =Inc_Statement!C26 -> 10557 | D5: =Inc_Statement!D26 -> 8190 | E5: =Inc_Statement!E26 -> 8986 | F5: =Inc_Statement!F26 -> 14459 | G5: 20027 | H5: =Inc_Statement!H26 -> 20378 | I5: =Inc_Statement!I26 -> 25448 | J5: =Inc_Statement!J26 -> 30678 | K5: =Inc_Statement!K26 -> 35725
B6: Add: Depreciation & Amortisation | C6: =Assumptions!C29 -> 6007 | D6: =Assumptions!D29 -> 6152 | E6: =Assumptions!E29 -> 6870 | F6: =Assumptions!F29 -> 7575 | G6: 8761 | H6: =Assumptions!H29 -> 8900 | I6: =Assumptions!I29 -> 9500 | J6: =Assumptions!J29 -> 10000 | K6: =Assumptions!K29 -> 10500
B7: Add: Interest Charged | C7: =Assumptions!C30 -> 3786 | D7: =Assumptions!D30 -> 3808 | E7: =Assumptions!E30 -> 4494 | F7: =Assumptions!F30 -> 4585 | G7: 4496 | H7: =Assumptions!H30 -> 4200 | I7: =Assumptions!I30 -> 4000 | J7: =Assumptions!J30 -> 3800 | K7: =Assumptions!K30 -> 3600
B8: (Increase)/Decrease in Working Capital | C8: -4630 | D8: -4500 | E8: -1928 | F8: -6039 | G8: -5700 | H8: =-(Bal_Sheet!H18-Bal_Sheet!G18)+(Bal_Sheet!H22-Bal_Sheet!G22)-(Bal_Sheet!H19-Bal_Sheet!G19) -> -523 | I8: =-(Bal_Sheet!I18-Bal_Sheet!H18)+(Bal_Sheet!I22-Bal_Sheet!H22)-(Bal_Sheet!I19-Bal_Sheet!H19) -> -1232 | J8: =-(Bal_Sheet!J18-Bal_Sheet!I18)+(Bal_Sheet!J22-Bal_Sheet!I22)-(Bal_Sheet!J19-Bal_Sheet!I19) -> -2123 | K8: =-(Bal_Sheet!K18-Bal_Sheet!J18)+(Bal_Sheet!K22-Bal_Sheet!J22)-(Bal_Sheet!K19-Bal_Sheet!J19) -> -2076
B9: Less: Tax Paid | C9: =-Assumptions!C32*MAX(Inc_Statement!C23,0) -> -4765.862 | D9: =-Assumptions!D32*MAX(Inc_Statement!D23,0) -> -2562.336 | E9: =-Assumptions!E32*MAX(Inc_Statement!E23,0) -> -4455.375 | F9: =-Assumptions!F32*MAX(Inc_Statement!F23,0) -> -5336.226 | G9: -6582 | H9: =-Assumptions!H32*MAX(Inc_Statement!H23,0) -> -7648.02 | I9: =-Assumptions!I32*MAX(Inc_Statement!I23,0) -> -9530.46 | J9: =-Assumptions!J32*MAX(Inc_Statement!J23,0) -> -11472.3 | K9: =-Assumptions!K32*MAX(Inc_Statement!K23,0) -> -13346.37
B10: Cash from Operations (CFO) | C10: 16156 | D10: 13771 | E10: 19202 | F10: 21364 | G10: 28557 | H10: =H5+H6+H7+H8+H9 -> 25306.98 | I10: =I5+I6+I7+I8+I9 -> 28185.54 | J10: =J5+J6+J7+J8+J9 -> 30882.7 | K10: =K5+K6+K7+K8+K9 -> 34402.63
B11: B. CASH FROM INVESTING (INR Mn)
B12: Capital Expenditure (Capex) | C12: =-Assumptions!C35 -> -6518 | D12: =-Assumptions!D35 -> -11285 | E12: =-Assumptions!E35 -> -11349 | F12: =-Assumptions!F35 -> -16978 | G12: -19620 | H12: =-Assumptions!H35 -> -15000 | I12: =-Assumptions!I35 -> -12000 | J12: =-Assumptions!J35 -> -10000 | K12: =-Assumptions!K35 -> -10000
B13: Other Investing (net) | C13: -1389 | D13: -3421 | E13: -4023 | F13: -16828 | G13: -1862 | H13: -1500 | I13: -1500 | J13: -1500 | K13: -1500
B14: Cash from Investing (CFI) | C14: =C12+C13 -> -7907 | D14: =D12+D13 -> -14706 | E14: =E12+E13 -> -15372 | F14: =F12+F13 -> -33806 | G14: -21482 | H14: =H12+H13 -> -16500 | I14: =I12+I13 -> -13500 | J14: =J12+J13 -> -11500 | K14: =K12+K13 -> -11500
B15: C. CASH FROM FINANCING (INR Mn)
B16: Net Debt Raised/(Repaid) | C16: -2866 | D16: 688 | E16: 2246 | F16: 18525 | G16: 3809 | H16: -5000 | I16: -5000 | J16: -4000 | K16: -4000
B17: Interest Paid | C17: -3764 | D17: -2514 | E17: -3029 | F17: -3018 | G17: -4466 | H17: =-Assumptions!H30 -> -4200 | I17: =-Assumptions!I30 -> -4000 | J17: =-Assumptions!J30 -> -3800 | K17: =-Assumptions!K30 -> -3600
B18: Dividends Paid | C18: -433 | D18: -2579 | E18: -2209 | F18: -2784 | G18: -2876 | H18: -720 | I18: -720 | J18: -720 | K18: -720
B19: Cash from Financing (CFF) | C19: =C16+C17+C18 -> -7063 | D19: =D16+D17+D18 -> -4405 | E19: =E16+E17+E18 -> -2992 | F19: =F16+F17+F18 -> 12723 | G19: -3533 | H19: =H16+H17+H18 -> -9920 | I19: =I16+I17+I18 -> -9720 | J19: =J16+J17+J18 -> -8520 | K19: =K16+K17+K18 -> -8320
B20: D. SUMMARY
B21: Net Change in Cash | C21: =C10+C14+C19 -> 1186 | D21: =D10+D14+D19 -> -5340 | E21: =E10+E14+E19 -> 838 | F21: =F10+F14+F19 -> 281 | G21: =G10+G14+G19 -> 3542 | H21: =H10+H14+H19 -> -1113.02 | I21: =I10+I14+I19 -> 4965.54 | J21: =J10+J14+J19 -> 10862.7 | K21: =K10+K14+K19 -> 14582.63
B22: Free Cash Flow (FCF = CFO + Capex) | C22: =C10+C12 -> 9638 | D22: =D10+D12 -> 2486 | E22: =E10+E12 -> 7853 | F22: =F10+F12 -> 4386 | G22: 8937 | H22: =H10+H12 -> 10306.98 | I22: =I10+I12 -> 16185.54 | J22: =J10+J12 -> 20882.7 | K22: =K10+K12 -> 24402.63
B23: FCF Yield (% of Market Cap — ref only) | C23: =IF(C22=0,"",C22/1098013) -> 0.0087776739 | D23: =IF(D22=0,"",D22/1098013) -> 0.0022640898 | E23: =IF(E22=0,"",E22/1098013) -> 0.00715201 | F23: =IF(F22=0,"",F22/1098013) -> 0.0039944882 | G23: =IF(G22=0,"",G22/1098013) -> 0.0081392479 | H23: =IF(H22=0,"",H22/1098013) -> 0.009386938 | I23: =IF(I22=0,"",I22/1098013) -> 0.014740754 | J23: =IF(J22=0,"",J22/1098013) -> 0.019018627 | K23: =IF(K22=0,"",K22/1098013) -> 0.022224354

Sheet Hosp_Val
B1: HOSPITAL SEGMENT VALUATION | EV/EBITDA + Forward P/E | INR Millions
B2: Primary: EV/EBITDA. Cross-check: Forward P/E. Peer table included. Reference CMP: ₹7,636 (Apr 2026). Shares: 143.8 Mn.
B4: A. PEER BENCHMARKING — Hospital Sector (FY25/26, approximate)
B5: Company | C5: EV/EBITDA (FY25) | D5: EV/EBITDA (FY26E) | E5: P/E (FY25) | F5: P/E (FY26E) | G5: EBITDA Margin | H5: Occ Rate | I5: ARPOB (₹k/day)
B6: Apollo Hospitals (APHS) | C6: 34.1 | D6: 29 | E6: 68.5 | F6: 56.9 | G6: 13.9% | H6: 69% | I6: 60.5
B7: Max Healthcare (MAXHEALTH) | C7: 38 | D7: 32 | E7: 75 | F7: 60 | G7: 18.0% | H7: 72% | I7: 55
B8: Fortis Healthcare (FORTIS) | C8: 36 | D8: 30 | E8: 68 | F8: 55 | G8: 11.0% | H8: 65% | I8: 42
B9: Narayana Hrudayalaya (NH) | C9: 24 | D9: 20 | E9: 41 | F9: 34 | G9: 14.5% | H9: 62% | I9: 28
B10: Aster DM Healthcare (ASTER) | C10: 22 | D10: 19 | E10: 50 | F10: 38 | G10: 9.5% | H10: 58% | I10: 32
B11: Note: Apollo commanded premium to peers given integrated platform. Post-demerger, pure-play hospital comps (Max, NH) become more relevant benchmarks.
B13: B. EV/EBITDA VALUATION — Hospital Business (FY26E/FY27E)
B14: Hospital EBITDA — FY26A (INR Mn) | C14: =Inc_Statement!F11 -> 27283
B15: Hospital EBITDA — FY26E (INR Mn) | C15: =Inc_Statement!G11 -> 29580
B16: Hospital EBITDA — FY27E (INR Mn) | C16: =Inc_Statement!H11 -> 35351
B17: Net Debt — FY26A (INR Mn) | C17: =Assumptions!C47 -> 39150
B18: Minority Interest (INR Mn) | C18: =Assumptions!C48 -> 4406
B19: Shares Outstanding (Mn) | C19: 143.8
B21: B1. EV/EBITDA SENSITIVITY TABLE — Implied Price per Share (INR)
B22: EV/EBITDA Multiple | C22: Hosp EV (FY26E EBITDA) | D22: Equity Val (FY26E) | E22: Price/Share (FY26E) | F22: Hosp EV (FY27E EBITDA) | G22: Equity Val (FY27E) | H22: Price/Share (FY27E)
B23: 22x | C23: =22*C15 -> 650760 | D23: =22*C15-C17-C18 -> 607204 | E23: =(22*C15-C17-C18)/143.8 -> 4222.5591 | F23: =22*C16 -> 777722 | G23: =22*C16-C17-C18 -> 734166 | H23: =(22*C16-C17-C18)/143.8 -> 5105.4659
B24: 24x | C24: =24*C15 -> 709920 | D24: =24*C15-C17-C18 -> 666364 | E24: =(24*C15-C17-C18)/143.8 -> 4633.9638 | F24: =24*C16 -> 848424 | G24: =24*C16-C17-C18 -> 804868 | H24: =(24*C16-C17-C18)/143.8 -> 5597.1349
B25: 26x | C25: =26*C15 -> 769080 | D25: =26*C15-C17-C18 -> 725524 | E25: =(26*C15-C17-C18)/143.8 -> 5045.3686 | F25: =26*C16 -> 919126 | G25: =26*C16-C17-C18 -> 875570 | H25: =(26*C16-C17-C18)/143.8 -> 6088.8039
B26: 28x | C26: =28*C15 -> 828240 | D26: =28*C15-C17-C18 -> 784684 | E26: =(28*C15-C17-C18)/143.8 -> 5456.7733 | F26: =28*C16 -> 989828 | G26: =28*C16-C17-C18 -> 946272 | H26: =(28*C16-C17-C18)/143.8 -> 6580.4729
B27: 30x | C27: =30*C15 -> 887400 | D27: =30*C15-C17-C18 -> 843844 | E27: =(30*C15-C17-C18)/143.8 -> 5868.178 | F27: =30*C16 -> 1060530 | G27: =30*C16-C17-C18 -> 1016974 | H27: =(30*C16-C17-C18)/143.8 -> 7072.1419
B28: 32x | C28: =32*C15 -> 946560 | D28: =32*C15-C17-C18 -> 903004 | E28: =(32*C15-C17-C18)/143.8 -> 6279.5828 | F28: =32*C16 -> 1131232 | G28: =32*C16-C17-C18 -> 1087676 | H28: =(32*C16-C17-C18)/143.8 -> 7563.8108
B29: 34x | C29: =34*C15 -> 1005720 | D29: =34*C15-C17-C18 -> 962164 | E29: =(34*C15-C17-C18)/143.8 -> 6690.9875 | F29: =34*C16 -> 1201934 | G29: =34*C16-C17-C18 -> 1158378 | H29: =(34*C16-C17-C18)/143.8 -> 8055.4798
B30: 36x | C30: =36*C15 -> 1064880 | D30: =36*C15-C17-C18 -> 1021324 | E30: =(36*C15-C17-C18)/143.8 -> 7102.3922 | F30: =36*C16 -> 1272636 | G30: =36*C16-C17-C18 -> 1229080 | H30: =(36*C16-C17-C18)/143.8 -> 8547.1488
B31: 38x | C31: =38*C15 -> 1124040 | D31: =38*C15-C17-C18 -> 1080484 | E31: =(38*C15-C17-C18)/143.8 -> 7513.7969 | F31: =38*C16 -> 1343338 | G31: =38*C16-C17-C18 -> 1299782 | H31: =(38*C16-C17-C18)/143.8 -> 9038.8178
B32: ← Highlighted row (28x) = base case multiple. Net debt includes bank borrowings; excludes lease liabilities.
B34: C. FORWARD P/E VALUATION — Consolidated (Cross-check)
B35: P/E Multiple | C35: EPS FY26E | D35: Price (FY26E) | E35: EPS FY27E | F35: Price (FY27E)
B36: 35x | C36: =Inc_Statement!G28 -> 135.04 | D36: =35*Inc_Statement!G28 -> 4726.4 | E36: =Inc_Statement!H28 -> 141.71071 | F36: =35*Inc_Statement!H28 -> 4959.8748
B37: 40x | C37: =Inc_Statement!G28 -> 135.04 | D37: =40*Inc_Statement!G28 -> 5401.6 | E37: =Inc_Statement!H28 -> 141.71071 | F37: =40*Inc_Statement!H28 -> 5668.4284
B38: 44x | C38: =Inc_Statement!G28 -> 135.04 | D38: =44*Inc_Statement!G28 -> 5941.76 | E38: =Inc_Statement!H28 -> 141.71071 | F38: =44*Inc_Statement!H28 -> 6235.2712
B39: 45x | C39: =Inc_Statement!G28 -> 135.04 | D39: =45*Inc_Statement!G28 -> 6076.8 | E39: =Inc_Statement!H28 -> 141.71071 | F39: =45*Inc_Statement!H28 -> 6376.9819
B40: 50x | C40: =Inc_Statement!G28 -> 135.04 | D40: =50*Inc_Statement!G28 -> 6752 | E40: =Inc_Statement!H28 -> 141.71071 | F40: =50*Inc_Statement!H28 -> 7085.5355
B41: 52x | C41: =Inc_Statement!G28 -> 135.04 | D41: =52*Inc_Statement!G28 -> 7022.08 | E41: =Inc_Statement!H28 -> 141.71071 | F41: =52*Inc_Statement!H28 -> 7368.9569
B42: 55x | C42: =Inc_Statement!G28 -> 135.04 | D42: =55*Inc_Statement!G28 -> 7427.2 | E42: =Inc_Statement!H28 -> 141.71071 | F42: =55*Inc_Statement!H28 -> 7794.089
B43: 60x | C43: =Inc_Statement!G28 -> 135.04 | D43: =60*Inc_Statement!G28 -> 8102.4 | E43: =Inc_Statement!H28 -> 141.71071 | F43: =60*Inc_Statement!H28 -> 8502.6426
B44: ← Highlighted row (45x) = base case. Pure-play hospital post-demerger: Max ~40-55x, NH ~35-42x. Apollo premium 45-52x range is appropriate.

Sheet Pharmacy_Hlth
B1: APOLLO HEALTHCO — Pharmacy + Apollo 24/7 | Simple Model | INR Millions
B2: DEMERGER: Apollo Healthco + Keimed to be merged into new listed entity Apollo Healthtech Ltd (AHTL). NCLT order Mar 2026. This business will be separately listed post-scheme. Valuation on EV/Sales and EV/EBITDA once profitable.
A3: Description | B3: INR Mn | C3: FY22A | D3: FY23A | E3: FY24A | F3: FY25A | G3: FY26A | H3: FY27E | I3: FY28E | J3: FY29E | K3: FY30E
B4: A. REVENUE MODEL
B5: Healthco Total Revenue (INR Mn) | C5: =Assumptions!C13 -> 53626 | D5: =Assumptions!D13 -> 67124 | E5: =Assumptions!E13 -> 78269 | F5: =Assumptions!F13 -> 90930 | G5: =Assumptions!G13 -> 108081 | H5: =Assumptions!H13 -> 125600 | I5: =Assumptions!I13 -> 144400 | J5: =Assumptions!J13 -> 164600 | K5: =Assumptions!K13 -> 184400
B6: Offline Pharmacy Revenue (INR Mn) | C6: 45000 | D6: 55000 | E6: 67400 | F6: 80000 | G6: =ROUND(Pharmacy_Hlth!G5*0.87,0) -> 94030 | H6: =ROUND(Pharmacy_Hlth!H5*0.87,0) -> 109272 | I6: =ROUND(Pharmacy_Hlth!I5*0.87,0) -> 125628 | J6: =ROUND(Pharmacy_Hlth!J5*0.87,0) -> 143202 | K6: =ROUND(Pharmacy_Hlth!K5*0.87,0) -> 160428
B7: Apollo 24/7 Revenue (GMV × Take Rate ≈37-45%) | C7: 8626 | D7: 12124 | E7: 10869 | F7: 10930 | G7: =ROUND(Pharmacy_Hlth!G5*0.13,0) -> 14051 | H7: =ROUND(Pharmacy_Hlth!H5*0.13,0) -> 16328 | I7: =ROUND(Pharmacy_Hlth!I5*0.13,0) -> 18772 | J7: =ROUND(Pharmacy_Hlth!J5*0.13,0) -> 21398 | K7: =ROUND(Pharmacy_Hlth!K5*0.13,0) -> 23972
B8: Revenue Growth (%) | D8: =IF(C5=0,"",D5/C5-1) -> 0.25170626 | E8: =IF(D5=0,"",E5/D5-1) -> 0.16603599 | F8: =IF(E5=0,"",F5/E5-1) -> 0.16176264 | G8: =IF(F5=0,"",G5/F5-1) -> 0.18861762 | H8: =IF(G5=0,"",H5/G5-1) -> 0.16209139 | I8: =IF(H5=0,"",I5/H5-1) -> 0.14968153 | J8: =IF(I5=0,"",J5/I5-1) -> 0.1398892 | K8: =IF(J5=0,"",K5/J5-1) -> 0.12029162
B9: B. EBITDA & PROFITABILITY
B10: EBITDA Margin (%) | C10: =Assumptions!C20 -> 0.005 | D10: =Assumptions!D20 -> 0.008 | E10: =Assumptions!E20 -> 0.01 | F10: =Assumptions!F20 -> 0.014 | G10: =Assumptions!G20 -> 0.088 | H10: =Assumptions!H20 -> 0.028 | I10: =Assumptions!I20 -> 0.038 | J10: =Assumptions!J20 -> 0.045 | K10: =Assumptions!K20 -> 0.05
B11: EBITDA (INR Mn) | C11: =ROUND(C5*C10,0) -> 268 | D11: =ROUND(D5*D10,0) -> 537 | E11: =ROUND(E5*E10,0) -> 783 | F11: =ROUND(F5*F10,0) -> 1273 | G11: =ROUND(G5*G10,0) -> 9511 | H11: =ROUND(H5*H10,0) -> 3517 | I11: =ROUND(I5*I10,0) -> 5487 | J11: =ROUND(J5*J10,0) -> 7407 | K11: =ROUND(K5*K10,0) -> 9220
B12: GMV — Apollo 24/7 (INR Mn) | C12: 14000 | D12: 18000 | E12: 25000 | F12: 30000 | G12: 37500 | H12: 47000 | I12: 58000 | J12: 72000 | K12: 88000
B13: Pharmacy Store Count (end of period) | C13: 4200 | D13: 5200 | E13: 6030 | F13: 6626 | G13: 7226 | H13: 7826 | I13: 8426 | J13: 9026 | K13: 9626
B14: C. VALUATION — Apollo Healthco / AHTL (Post-Demerger)
B15: Post-demerger, AHTL (Healthco + Keimed) will be separately listed. Valuation uses EV/Sales (since EBITDA is small/near breakeven in near-term) and EV/EBITDA (once profitable by FY27). Comps: Bright-Chemist, PharmEasy (unlisted); closest listed proxy = Tata 1mg (unlisted), MedPlus.
B16: EV/Sales Multiple — Base Case | C16: 2
B17: EV/Sales Multiple — Bull Case | C17: 3
B18: EV/EBITDA Multiple (FY27E) | C18: 25
B19: Healthco Revenue FY26E (INR Mn) | C19: =G5 -> 108081
B20: Healthco Revenue FY27E (INR Mn) | C20: =H5 -> 125600
B21: Healthco EBITDA FY27E (INR Mn) | C21: =H11 -> 3517
B22: Implied EV — EV/Sales Base (INR Mn) | C22: =C16*C19 -> 216162
B23: Implied EV — EV/EBITDA FY27E (INR Mn) | C23: =C18*C21 -> 87925

Sheet Diag_AHLL
B1: APOLLO HEALTH & LIFESTYLE (AHLL) — Diagnostics + Primary Care | INR Millions
B2: AHLL: Diagnostics + Primary Care (Apollo Clinic) + Specialty Care + Cradle. Retained within AHEL post-demerger. Simple top-down model.
A3: Description | B3: INR Mn | C3: FY22A | D3: FY23A | E3: FY24A | F3: FY25A | G3: FY26A | H3: FY27E | I3: FY28E | J3: FY29E | K3: FY30E
B4: A. REVENUE MODEL
B5: AHLL Total Revenue (INR Mn) | C5: =Assumptions!C15 -> 13000 | D5: =Assumptions!D15 -> 12000 | E5: =Assumptions!E15 -> 13653 | F5: =Assumptions!F15 -> 15535 | G5: =Assumptions!G15 -> 16703 | H5: =Assumptions!H15 -> 19660 | I5: =Assumptions!I15 -> 21820 | J5: =Assumptions!J15 -> 24000 | K5: =Assumptions!K15 -> 26400
B6: Diagnostics (INR Mn) | C6: 5850 | D6: 5450 | E6: 5010 | F6: 5460 | G6: =ROUND(Diag_AHLL!G5*0.35,0) -> 5846 | H6: =ROUND(Diag_AHLL!H5*0.35,0) -> 6881 | I6: =ROUND(Diag_AHLL!I5*0.35,0) -> 7637 | J6: =ROUND(Diag_AHLL!J5*0.35,0) -> 8400 | K6: =ROUND(Diag_AHLL!K5*0.35,0) -> 9240
B7: Primary Care / Apollo Clinic (INR Mn) | C7: 2730 | D7: 2600 | E7: 3240 | F7: 3660 | G7: =ROUND(Diag_AHLL!G5*0.21,0) -> 3508 | H7: =ROUND(Diag_AHLL!H5*0.21,0) -> 4129 | I7: =ROUND(Diag_AHLL!I5*0.21,0) -> 4582 | J7: =ROUND(Diag_AHLL!J5*0.21,0) -> 5040 | K7: =ROUND(Diag_AHLL!K5*0.21,0) -> 5544
B8: Specialty Care (INR Mn) | C8: 4420 | D8: 3950 | E8: 5400 | F8: 6420 | G8: =ROUND(Diag_AHLL!G5*0.44,0) -> 7349 | H8: =ROUND(Diag_AHLL!H5*0.44,0) -> 8650 | I8: =ROUND(Diag_AHLL!I5*0.44,0) -> 9601 | J8: =ROUND(Diag_AHLL!J5*0.44,0) -> 10560 | K8: =ROUND(Diag_AHLL!K5*0.44,0) -> 11616
B9: Revenue Growth (%) | D9: =IF(C5=0,"",D5/C5-1) -> -0.076923077 | E9: =IF(D5=0,"",E5/D5-1) -> 0.13775 | F9: =IF(E5=0,"",F5/E5-1) -> 0.13784516 | G9: =IF(F5=0,"",G5/F5-1) -> 0.075185066 | H9: =IF(G5=0,"",H5/G5-1) -> 0.17703407 | I9: =IF(H5=0,"",I5/H5-1) -> 0.10986775 | J9: =IF(I5=0,"",J5/I5-1) -> 0.099908341 | K9: =IF(J5=0,"",K5/J5-1) -> 0.1
B10: B. EBITDA & PROFITABILITY
B11: EBITDA Margin (%) | C11: =Assumptions!C21 -> 0.087 | D11: =Assumptions!D21 -> 0.093 | E11: =Assumptions!E21 -> 0.096 | F11: =Assumptions!F21 -> 0.107 | G11: =Assumptions!G21 -> 0.135 | H11: =Assumptions!H21 -> 0.125 | I11: =Assumptions!I21 -> 0.13 | J11: =Assumptions!J21 -> 0.135 | K11: =Assumptions!K21 -> 0.14
B12: AHLL EBITDA (INR Mn) | C12: =ROUND(C5*C11,0) -> 1131 | D12: =ROUND(D5*D11,0) -> 1116 | E12: =ROUND(E5*E11,0) -> 1311 | F12: =ROUND(F5*F11,0) -> 1662 | G12: =ROUND(G5*G11,0) -> 2255 | H12: =ROUND(H5*H11,0) -> 2458 | I12: =ROUND(I5*I11,0) -> 2837 | J12: =ROUND(J5*J11,0) -> 3240 | K12: =ROUND(K5*K11,0) -> 3696
B13: Daily Footfalls (approx, pan-India) | C13: 15000 | D13: 17000 | E13: 19000 | F13: 23049 | G13: 26000 | H13: 29000 | I13: 32000 | J13: 35000 | K13: 38000
B14: C. VALUATION — AHLL (Retained in AHEL Post-Demerger)
B15: AHLL is retained within Apollo Hospitals post-demerger. Valued as part of AHEL on EV/EBITDA. Peer comps: Metropolis Healthcare (~25x EV/EBITDA), Dr Lal PathLabs (~28x), Vijaya Diagnostics (~22x). Primary care segment commands lower multiple. Blended 20x used for AHLL.
B16: EV/EBITDA Multiple — Base Case | C16: 20
B17: EV/EBITDA Multiple — Bull Case | C17: 24
B18: AHLL EBITDA FY26E (INR Mn) | C18: =G12 -> 2255
B19: AHLL EBITDA FY27E (INR Mn) | C19: =H12 -> 2458
B20: Implied AHLL EV — FY26E (INR Mn) | C20: =C16*C18 -> 45100

Sheet SOTP
B1: SUM-OF-THE-PARTS VALUATION | Apollo Hospitals Enterprise Ltd | INR Millions
B2: Pre-demerger: AHEL valued as conglomerate. Post-demerger: AHEL = pure-play hospital + AHLL; AHTL (Healthco) = separately listed. AHEL shareholders receive AHTL shares on demerger record date.
B4: Component | C4: Methodology | D4: Multiple / Rate | E4: EBITDA / Base (INR Mn) | F4: Implied EV (INR Mn) | G4: Value / Share (INR)
B5: PRE-DEMERGER SOTP (AHEL as integrated healthcare platform — FY26E)
B6: Hospital Business | C6: EV/EBITDA (FY26E) | D6: 27 | E6: =Inc_Statement!G11 -> 29580 | F6: =D6*E6 -> 798660 | G6: =F6/143.8 -> 5553.9638
B7: Apollo Healthco (Pharmacy + 24/7) | C7: EV/Revenue (FY26E) | D7: 2 | E7: =Pharmacy_Hlth!G5 -> 108081 | F7: =D7*E7 -> 216162 | G7: =F7/143.8 -> 1503.2128
B8: AHLL (Diagnostics + Primary Care) | C8: EV/EBITDA (FY26E) | D8: 20 | E8: =Diag_AHLL!G12 -> 2255 | F8: =D8*E8 -> 45100 | G8: =F8/143.8 -> 313.63004
B9: Total Segment EV (Sum of Parts) | F9: =F6+F7+F8 -> 1059922 | G9: =F9/143.8 -> 7370.8067
B10: Less: Conglomerate / Holdco Discount (%) | C10: Pre-demerger integrated discount | D10: 0.07 | F10: =-D10*F9 -> -74194.54
B11: Less: Net Debt (Bank Borrowings – Cash, FY25A) | F11: -39150
B12: Less: Minority Interest (FY25A) | F12: -4406
B13: Equity Value — Pre-Demerger (INR Mn) | F13: =F9+F10+F11+F12 -> 942171.46 | G13: =F13/143.8 -> 6551.9573
B14: CMP (Reference) | F14: 7636 | G14: 7636
B15: Implied Upside / (Downside) — Pre-Demerger | G15: =G13/G14-1 -> -0.14196473
B17: POST-DEMERGER SOTP (AHEL = pure-play hospital + AHLL; AHTL = Healthco separately listed)
B18: Post-demerger, each AHEL shareholder receives AHTL shares in exchange ratio (TBD at scheme finalization). AHEL (rump) = hospital + AHLL. AHTL = pharmacy + digital health + Keimed. Pure-play hospital multiple may expand; conglomerate discount eliminated.
B19: AHEL (Rump) — Hospital + AHLL | C19: Methodology | D19: Multiple | E19: EBITDA (FY26E) | F19: Implied EV (INR Mn) | G19: Value / Share (INR)
B20: Hospital Business (pure-play premium post-demerger) | C20: EV/EBITDA (FY26E) | D20: 30 | E20: =Inc_Statement!G11 -> 29580 | F20: =D20*E20 -> 887400 | G20: =F20/143.8 -> 6171.0709
B21: AHLL (retained — diagnostics + primary care) | C21: EV/EBITDA (FY26E) | D21: 20 | E21: =Diag_AHLL!G12 -> 2255 | F21: =D21*E21 -> 45100 | G21: =F21/143.8 -> 313.63004
B22: AHEL Total EV (Hospital + AHLL) | F22: =F20+F21 -> 932500 | G22: =F22/143.8 -> 6484.701
B23: Less: Net Debt (allocated to AHEL rump, FY25A) | F23: -28000
B24: Less: Minority Interest (AHEL rump) | F24: -4406
B25: AHEL Equity Value (Post-Demerger) | F25: =F22+F23+F24 -> 900094 | G25: =F25/143.8 -> 6259.3463
B27: AHTL (Demerged Healthco) — Value Accruing to AHEL Shareholders
B28: Apollo Healthtech Ltd (AHTL) — implied EV (FY26E EV/Sales) | C28: EV/Revenue (FY26E) | D28: 2 | E28: =Pharmacy_Hlth!G5 -> 108081 | F28: =D28*E28 -> 216162 | G28: =F28/143.8 -> 1503.2128
B29: Less: Debt Allocated to AHTL (INR Mn) | F29: -11150
B30: AHTL Equity Value (to AHEL shareholders) | F30: =F28+F29 -> 205012 | G30: =F30/143.8 -> 1425.6745
B32: COMBINED POST-DEMERGER VALUE TO AHEL SHAREHOLDERS (AHEL + AHTL) | F32: =F25+F30 -> 1105106 | G32: =F32/143.8 -> 7685.0209
B33: Reference CMP (INR/share) | G33: 7636
B34: Implied Upside / (Downside) — Post-Demerger Combined | G34: =G32/G33-1 -> 0.0064197043
B36: ANALYST NOTE — DEMERGER IMPACT ON VALUATION: Pre-demerger: Apollo commanded 30-35x EV/EBITDA as an integrated platform (conglomerate premium). Post-demerger: (1) AHEL (hospital) may trade at 30-35x EV/EBITDA as pure-play (inline with Max Healthcare). (2) AHTL (pharmacy/digital) valued on EV/Sales until profitable — near-term drag. (3) Net effect: demerger likely value-neutral to slightly value-accretive IF hospital gets re-rated as pure-play and AHTL reaches EBITDA breakeven (management guides Q2/Q3 FY26). Conglomerate discount eliminated. Key risk: AHTL loses cross-sell synergies; hospital loses pharmacy distribution network. Analyst should stress-test AHTL at 1x-3x EV/Sales.

Sheet Return_Ratios
B1: RETURN RATIOS & CREDIT METRICS | Apollo Hospitals Enterprise Ltd | INR Millions
B2: All ratios derived from Inc_Statement, Bal_Sheet, and Cash_Flow. FCF = CFO – Capex (capex shown as negative in CF). ROCE uses average capital employed.
A3: Description | C3: FY22A | D3: FY23A | E3: FY24A | F3: FY25A | G3: FY26A | H3: FY27E | I3: FY28E | J3: FY29E | K3: FY30E
B4: A. PROFITABILITY & RETURNS
B5: Revenue (INR Mn) [ref] | C5: =Inc_Statement!C8 -> 146626 | D5: =Inc_Statement!D8 -> 166124 | E5: =Inc_Statement!E8 -> 190558 | F5: =Inc_Statement!F8 -> 217940 | G5: =Inc_Statement!G8 -> 252285 | H5: =Inc_Statement!H8 -> 289550 | I5: =Inc_Statement!I8 -> 330609 | J5: =Inc_Statement!J8 -> 373676 | K5: =Inc_Statement!K8 -> 415756
B6: EBITDA (INR Mn) [ref] | C6: =Inc_Statement!C15 -> 21851 | D6: =Inc_Statement!D15 -> 20496 | E6: =Inc_Statement!E15 -> 23907 | F6: =Inc_Statement!F15 -> 30218 | G6: =Inc_Statement!G15 -> 37690 | H6: =Inc_Statement!H15 -> 39826 | I6: =Inc_Statement!I15 -> 47098 | J6: =Inc_Statement!J15 -> 54490 | K6: =Inc_Statement!K15 -> 61631
B7: EBIT (INR Mn) [ref] | C7: =Inc_Statement!C19 -> 15844 | D7: =Inc_Statement!D19 -> 14344 | E7: =Inc_Statement!E19 -> 17037 | F7: =Inc_Statement!F19 -> 22643 | G7: =Inc_Statement!G19 -> 28929 | H7: =Inc_Statement!H19 -> 30926 | I7: =Inc_Statement!I19 -> 37598 | J7: =Inc_Statement!J19 -> 44490 | K7: =Inc_Statement!K19 -> 51131
B8: PAT (INR Mn) [ref] | C8: =Inc_Statement!C26 -> 10557 | D8: =Inc_Statement!D26 -> 8190 | E8: =Inc_Statement!E26 -> 8986 | F8: =Inc_Statement!F26 -> 14459 | G8: =Inc_Statement!G26 -> 19419 | H8: =Inc_Statement!H26 -> 20378 | I8: =Inc_Statement!I26 -> 25448 | J8: =Inc_Statement!J26 -> 30678 | K8: =Inc_Statement!K26 -> 35725
B10: EBITDA Margin (%) | C10: =IF(Inc_Statement!C8=0,"",Inc_Statement!C15/Inc_Statement!C8) -> 0.14902541 | D10: =IF(Inc_Statement!D8=0,"",Inc_Statement!D15/Inc_Statement!D8) -> 0.12337772 | E10: =IF(Inc_Statement!E8=0,"",Inc_Statement!E15/Inc_Statement!E8) -> 0.12545787 | F10: =IF(Inc_Statement!F8=0,"",Inc_Statement!F15/Inc_Statement!F8) -> 0.13865284 | G10: =IF(Inc_Statement!G8=0,"",Inc_Statement!G15/Inc_Statement!G8) -> 0.14939453 | H10: =IF(Inc_Statement!H8=0,"",Inc_Statement!H15/Inc_Statement!H8) -> 0.13754447 | I10: =IF(Inc_Statement!I8=0,"",Inc_Statement!I15/Inc_Statement!I8) -> 0.14245831 | J10: =IF(Inc_Statement!J8=0,"",Inc_Statement!J15/Inc_Statement!J8) -> 0.14582151 | K10: =IF(Inc_Statement!K8=0,"",Inc_Statement!K15/Inc_Statement!K8) -> 0.14823839
B11: EBIT Margin (%) | C11: =IF(Inc_Statement!C8=0,"",Inc_Statement!C19/Inc_Statement!C8) -> 0.10805723 | D11: =IF(Inc_Statement!D8=0,"",Inc_Statement!D19/Inc_Statement!D8) -> 0.08634514 | E11: =IF(Inc_Statement!E8=0,"",Inc_Statement!E19/Inc_Statement!E8) -> 0.08940585 | F11: =IF(Inc_Statement!F8=0,"",Inc_Statement!F19/Inc_Statement!F8) -> 0.10389557 | G11: =IF(Inc_Statement!G8=0,"",Inc_Statement!G19/Inc_Statement!G8) -> 0.11466794 | H11: =IF(Inc_Statement!H8=0,"",Inc_Statement!H19/Inc_Statement!H8) -> 0.10680711 | I11: =IF(Inc_Statement!I8=0,"",Inc_Statement!I19/Inc_Statement!I8) -> 0.11372346 | J11: =IF(Inc_Statement!J8=0,"",Inc_Statement!J19/Inc_Statement!J8) -> 0.11906036 | K11: =IF(Inc_Statement!K8=0,"",Inc_Statement!K19/Inc_Statement!K8) -> 0.12298319
B12: Net Profit (PAT) Margin (%) | C12: =IF(Inc_Statement!C8=0,"",Inc_Statement!C26/Inc_Statement!C8) -> 0.071999509 | D12: =IF(Inc_Statement!D8=0,"",Inc_Statement!D26/Inc_Statement!D8) -> 0.049300523 | E12: =IF(Inc_Statement!E8=0,"",Inc_Statement!E26/Inc_Statement!E8) -> 0.047156246 | F12: =IF(Inc_Statement!F8=0,"",Inc_Statement!F26/Inc_Statement!F8) -> 0.066343948 | G12: =IF(Inc_Statement!G8=0,"",Inc_Statement!G26/Inc_Statement!G8) -> 0.076972472 | H12: =IF(Inc_Statement!H8=0,"",Inc_Statement!H26/Inc_Statement!H8) -> 0.070378173 | I12: =IF(Inc_Statement!I8=0,"",Inc_Statement!I26/Inc_Statement!I8) -> 0.076973101 | J12: =IF(Inc_Statement!J8=0,"",Inc_Statement!J26/Inc_Statement!J8) -> 0.08209786 | K12: =IF(Inc_Statement!K8=0,"",Inc_Statement!K26/Inc_Statement!K8) -> 0.085927804
B14: ROCE (EBIT / Capital Employed) (%) | C14: =IF((Bal_Sheet!C7+Bal_Sheet!C8+Bal_Sheet!C9)=0,"",Inc_Statement!C19/(Bal_Sheet!C7+Bal_Sheet!C8+Bal_Sheet!C9)) -> 0.18563127 | D14: =IF((Bal_Sheet!D7+Bal_Sheet!D8+Bal_Sheet!D9)=0,"",Inc_Statement!D19/(Bal_Sheet!D7+Bal_Sheet!D8+Bal_Sheet!D9)) -> 0.15521122 | E14: =IF((Bal_Sheet!E7+Bal_Sheet!E8+Bal_Sheet!E9)=0,"",Inc_Statement!E19/(Bal_Sheet!E7+Bal_Sheet!E8+Bal_Sheet!E9)) -> 0.16252957 | F14: =IF((Bal_Sheet!F7+Bal_Sheet!F8+Bal_Sheet!F9)=0,"",Inc_Statement!F19/(Bal_Sheet!F7+Bal_Sheet!F8+Bal_Sheet!F9)) -> 0.16257063 | G14: =IF((Bal_Sheet!G7+Bal_Sheet!G8+Bal_Sheet!G9)=0,"",Inc_Statement!G19/(Bal_Sheet!G7+Bal_Sheet!G8+Bal_Sheet!G9)) -> 0.17997835 | H14: =IF((Bal_Sheet!H7+Bal_Sheet!H8+Bal_Sheet!H9)=0,"",Inc_Statement!H19/(Bal_Sheet!H7+Bal_Sheet!H8+Bal_Sheet!H9)) -> 0.18539767 | I14: =IF((Bal_Sheet!I7+Bal_Sheet!I8+Bal_Sheet!I9)=0,"",Inc_Statement!I19/(Bal_Sheet!I7+Bal_Sheet!I8+Bal_Sheet!I9)) -> 0.20155787 | J14: =IF((Bal_Sheet!J7+Bal_Sheet!J8+Bal_Sheet!J9)=0,"",Inc_Statement!J19/(Bal_Sheet!J7+Bal_Sheet!J8+Bal_Sheet!J9)) -> 0.20936963 | K14: =IF((Bal_Sheet!K7+Bal_Sheet!K8+Bal_Sheet!K9)=0,"",Inc_Statement!K19/(Bal_Sheet!K7+Bal_Sheet!K8+Bal_Sheet!K9)) -> 0.20998357
